Workbook

Sheet Deligate_List
A1: OSMEC-ID | B1: FULL NAME | C1: institute | D1: event_category | E1: event_category1
A2: OSMEC-0004 | B2: MOHAMMED ABDUR RAHMAN | C2: Deccan College of Medical Sciences
A3: OSMEC-0005 | B3: QAZI SYED ABDULLAH | C3: Apollo Institute of Medical Sciences | D3: Case Presentation|349 | E3: Medquiz|40 Dare to Diagnose|40 Medventure|40
A4: OSMEC-0025 | B4: VULUVAPALLE SUROHAN REDDY | C4: Mediciti Institute Of Medical Sciences
A5: OSMEC-0006 | B5: Diya s bhandary | C5: Malla Reddy Institute Of Medical Sciences
A6: OSMEC-0009 | B6: S SADAF SUHANA AFROZE | C6: Dr VRK Womens Medical College | D6: Case Presentation|349 Medical Symposium|499
A7: OSMEC-0007 | B7: Nithin Kumar Punia | C7: Mediciti Institute Of Medical Sciences | D7: Case Presentation|349 | E7: Medquiz|40
A8: OSMEC-0016 | B8: Sri Sanjana Gunturi | C8: MNR Medical College | D8: Case Presentation|349
A9: OSMEC-0013 | B9: ABDUL RIYAAN AHMED | C9: Shadan Institute of Medical Sciences | D9: Medical Symposium|499
A10: OSMEC-0008 | B10: SUHAS KAVALI | C10: Kamineni Academy of Medical Sciences | D10: Case Presentation|349 | E10: Invictus|20
A11: OSMEC-0012 | B11: KASI ALEKHYA SRI | C11: Malla Reddy Medical College for Women | D11: Poster Presentation|349
A12: OSMEC-0023 | B12: Arshi Ameena Khan | C12: Dr VRK Womens Medical College | E12: Graphilia|20
A13: OSMEC-0011 | B13: SAFA MOHIUDDIN | C13: Deccan College of Medical Sciences | E13: Art Attack|20
A14: OSMEC-0010 | B14: PREETHAM GUPTHA | C14: Malla Reddy Institute of Medical Sciences | D14: Medical Symposium|499
A15: OSMEC-0014 | B15: SYEDA MAARIYA QUADRI | C15: Malla Reddy Medical College for Women | D15: Case Presentation|349 Medical Symposium|499
A16: OSMEC-0015 | B16: Abdus Sami Munquad | C16: Government Medical College, Siddipet | D16: Case Presentation|349 | E16: Medquiz|40 Medventure|40
A17: OSMEC-0017 | B17: DAANYA ATHAULLAH KHAN | C17: Deccan College of Medical Sciences | D17: Medical Symposium|499
A18: OSMEC-0018 | B18: PUPPALA VENKATA RATNA ANANTHA SAI NARAYANA | C18: NRI Medical College, Guntur | D18: Case Presentation|349 | E18: Invictus|20
A19: OSMEC-0019 | B19: HEVANSH KOTLA | C19: Maheshwara Medical College
A20: OSMEC-0020 | B20: MOHAMMED MUBASHEER ALI | C20: Kamineni Academy of Medical Sciences | E20: Medquiz|40 Dare to Diagnose|40 Shutter Medics|20 Medventure|40
A21: OSMEC-0021 | B21: C. HARI CHANDANA | C21: Dr Patnam Mahender Reddy Institute of Medical Sciences | D21: Case Presentation|349
A22: OSMEC-0042 | B22: DIGVIJAY DHUMAL | C22: Bhaskar Medical College | E22: Medquiz|40 Dare to Diagnose|40 Shutter Medics|20 Medventure|40
A23: OSMEC-0026 | B23: MEGHNA RAGHURAMAN | C23: Prathima Institute Of Medical Sciences | E23: Dare to Diagnose|40
A24: OSMEC-0024 | B24: Emily Justine Beera | C24: Apollo Institute of Medical Sciences | D24: Case Presentation|349
A25: OSMEC-0022 | B25: REVA SADDI | C25: Apollo Institute of Medical Sciences | D25: Case Presentation|349 | E25: Graphilia|20 Medventure|40
A26: OSMEC-0027 | B26: BHAMIDIPATI V S S S KAUSHIK | C26: Prathima Institute Of Medical Sciences | D26: Medical Symposium|499 | E26: Medquiz|40 Dare to Diagnose|40 Debate|40 Medventure|40
A27: OSMEC-0033 | B27: SNIGDHADEVASANI | C27: Government Medical College, Mahbubnagar
A28: OSMEC-0029 | B28: FURKHAN UMER AHMED | C28: Apollo Institute of Medical Sciences
A29: OSMEC-0037 | B29: FATIMA QUADIR | C29: Bhaskar Medical College | E29: Medquiz|40 Dare to Diagnose|40 Shutter Medics|20 Medventure|40
A30: OSMEC-0030 | B30: MOHTASHIM IDREES AKHTAR | C30: Deccan College of Medical Sciences | D30: Medical Symposium|499
A31: OSMEC-0031 | B31: POOJA KADARI | C31: Mallareddy Medical College | D31: Poster Presentation|349 | E31: Art Attack|20 Shutter Medics|20 Debate|40 Graphilia|20
A32: OSMEC-0028 | B32: ANVITHA DENDI | C32: Kamineni Institute of Medical Sciences Narketpally | D32: Case Presentation|349 Poster Presentation|349 | E32: Art Attack|20 Graphilia|20 Invictus|20
A33: OSMEC-0081 | B33: SOBIYA JHOZI MOHIUDDIN | C33: Deccan College of Medical Sciences
A34: OSMEC-0032 | B34: MOKUGU SHONITH | C34: Chalmeda Medical College Karimnagar | D34: Case Presentation|349 | E34: Debate|40
A35: OSMEC-0244 | B35: HASINI NANCHERI | C35: Prathima relief institute of medical sciences
A36: OSMEC-0034 | B36: BENJARAM NAVANEETH REDDY | C36: Prathima Institute of medical sciences
A37: OSMEC-0039 | B37: KHUSHI SHARMA | C37: Prathima Institute Of Medical Sciences | D37: Case Presentation|349 Medical Symposium|499 | E37: Medquiz|40 Shutter Medics|20
A38: OSMEC-0038 | B38: MANDADI ANNIE BENEDICTA | C38: Government Medical College, Nizamabad | D38: Case Presentation|349
A39: OSMEC-0041 | B39: MUHAMMAD ASHAZ HUSSAIN | C39: Deccan College of Medical Sciences
A40: OSMEC-0245 | B40: SYEDA KHADIJA ABBAS | C40: Shadan Institute of Medical Sciences | D40: Poster Presentation|349 Medical Symposium|499
...

Sheet Workshop
A1: WORKSHOP | B1: LOCATION | C1: WorkshopID
A2: Arterial Blood Gas Analysis | B2: 4TH FLOOR, ACADEMIC BLOCK | C2: W001
A3: Basic Life Support | B3: 6TH FLOOR, ACADEMIC BLOCK | C3: W002
A4: Basic Surgical Skills | B4: SURGERY LECTURE HALL, MAIN BUILDING | C4: W003
A5: Cardiology | B5: 5TH FLOOR, ACADEMIC BLOCK | C5: W004
A6: Emergency and Trauma Care | B6: 4TH FLOOR, ACADEMIC BLOCK | C6: W005
A7: Forensic Medicine | B7: 1ST FLOOR, DEPARTMENT OF FORENSIC MEDICINE, MAIN BUILDING | C7: W006
A8: Imaging and Radiology | B8: 5TH FLOOR, ACADEMIC BLOCK | C8: W007
A9: Obstetrics and Neonatology | B9: 3RD FLOOR, ACADEMIC BLOCK | C9: W008
A10: Pulmonology | B10: 2ND FLOOR, ACADEMIC BLOCK | C10: W009
A11: Research Methodology | B11: GROUND FLOOR, MAIN BUILDING, DEPARTMENT OF COMMUNITY MEDICINE | C11: W010
A12: Simwar | B12: COLLEGE LIBRARY, MAIN BUILDING | C12: W011
... A14: Synergy in Diagnosis | B14: Department of Pathology, Main Building, First Floor. | C14: W013

Sheet Events
A1: EVENT | B1: EVENT_NAME | C1: LOCATION | D1: EVENTID
A2: Day_1_EVENT_1 | B2: Inaugration Ceremony with the Chief Guest | C2: AUDITORIUM | D2: E001
A3: Day_1_EVENT_2 | B3: Registration Check-In | C3: ACADEMIC BLOCK PARKING | D3: E002
A4: Day_1_EVENT_3 | B4: Case Presentation | C4: SURGERY LECTURE HALL 1,SURGERY LECTURE HALL 2,BIOCHEM LECTURE HALL | D4: E003
A5: Day_1_EVENT_4 | B5: Medical Symposium Prelims | C5: AUDITORIUM | D5: E004
A6: Day_2_EVENT_1 | B6: Registration Check-In | C6: ACADEMIC BLOCK PARKING | D6: E005
A7: Day_2_EVENT_2 | B7: Case Presentation | C7: ACADEMIC BLOCK 3RD FLOOR, 4TH FLOOR, 5TH FLOOR, 6TH FLOOR | D7: E006
A8: Day_2_EVENT_3 | B8: Paper Presentation | C8: SPM LECTURE HALL, BIOCHEM LECTURE HALL, SURGERY LECTURE HALL, FORENSIC MEDICINE LECTURE HALL | D8: E007
A9: Day_2_EVENT_4 | B9: Poster Presentation | C9: ACADEMIC BLOCK 2ND FLOOR ROOM 1, 2ND FLOOR ROOM 2 | D9: E008
A10: Day_2_EVENT_5 | B10: Medical Symposium Prelims | C10: AUDITORIUM | D10: E009
A11: Day_2_EVENT_6 | B11: Debate Prelims | C11: 3RD FLOOR | D11: E010
A12: Day_2_EVENT_7 | B12: Medventure | C12: MEDVENTURE | D12: E011
... A25: Day_3_EVENT_8 | B25: Valedictory Ceremony | C25: AUDITORIUM | D25: E024

Sheet Subjects
A1: SUBJECT | B1: SUBJECT_NAME | C1: LOCATION | D1: SubjectID
A2: Day_1_Event_3_Subject_1 | B2: OPTHALMOLOGY | C2: SURGERY LECTURE HALL 1 | D2: S001
A3: Day_1_Event_3_Subject_1 | B3: GENERAL MEDICINE 1 | C3: SURGERY LECTURE HALL 2 | D3: S002
A4: Day_1_Event_3_Subject_1 | B4: GENERAL MEDICINE 2 | C4: BIOCHEMISTRY LECTURE HALL | D4: S003
A5: Day_2_Event_2_Subject_1 | B5: DERMATOLOGY | C5: ACADEMIC BLOCK 3RD FLOOR | D5: S004
A6: Day_2_Event_2_Subject_1 | B6: GENERAL SURGERY | C6: ACADEMIC BLOCK 4TH FLOOR | D6: S005
A7: Day_2_Event_2_Subject_1 | B7: GENERAL MEDICINE 3 | C7: ACADEMIC BLOCK 4TH FLOOR | D7: S006
A8: Day_2_Event_2_Subject_1 | B8: ORTHOPAEDICS | C8: ACADEMIC BLOCK 5TH FLOOR | D8: S007
A9: Day_2_Event_2_Subject_1 | B9: ENT | C9: ACADEMIC BLOCK 5TH FLOOR | D9: S008
A10: Day_2_Event_2_Subject_1 | B10: OBGYN | C10: ACADEMIC BLOCK 6TH FLOOR | D10: S009
A11: Day_2_Event_3_Subject_1 | B11: SESSION 1 | C11: SPM LECTURE HALL | D11: S010
A12: Day_2_Event_3_Subject_1 | B12: SESSION 2 | C12: FORENSIC LECTURE HALL | D12: S011
... A21: Day_3_Event_3_Subject_1 | B21: POSTERS SESSION 2 | C21: ACADEMIC BLOCK 2ND FLOOR ROOM 2 | D21: S020

Sheet Days
A1: DAYID | B1: DAY
A2: D001 | B2: 1
A3: D002 | B3: 2
A4: D003 | B4: 3

Sheet Final
A1: OSMEC-ID | B1: FULL NAME | C1: WORKSHOP | D1: DAY_1_EVENT_1 | E1: DAY_1_EVENT_2 | F1: DAY_1_EVENT_3 | G1: DAY_1_EVENT_4 | H1: Day_2_EVENT_1 | I1: DAY_2_EVENT_2 | J1: DAY_2_EVENT_3 | K1: DAY_2_EVENT_4 | L1: DAY_2_EVENT_5 | M1: DAY_2_EVENT_6 | N1: DAY_2_EVENT_7 | O1: DAY_2_EVENT_8 | P1: DAY_2_EVENT_9 | Q1: DAY_2_EVENT_10 | R1: DAY_2_EVENT_11 | S1: DAY_2_EVENT_12 | T1: Day_3_EVENT_1 | U1: DAY_3_EVENT_2 | V1: DAY_3_EVENT_3 | W1: DAY_3_EVENT_4 | X1: DAY_3_EVENT_5 | Y1: DAY_3_EVENT_6 | Z1: DAY_3_EVENT_7 | AA1: Day_1_Event_3_Subject_1 | AB1: Day_2_Event_2_Subject_1 | AC1: Day_2_Event_3_Subject_1 | AD1: Day_2_Event_4_Subject_1 | AE1: Day_3_Event_2_Subject_1 | AF1: Day_3_Event_3_Subject_1
A2: =Deligate_List!A2 -> OSMEC-0004 | B2: =VLOOKUP(A2,Deligate_List!A:B,2,FALSE) -> MOHAMMED ABDUR RAHMAN | C2: =IFERROR( VLOOKUP( VLOOKUP($A2,'[1]OSMEC ID + WORKSHOP'!$A:$B,2,FALSE),Workshop!A:C,3,FALSE),"") -> W001 | D2: =IF($D$1 =Events!$A$2, VLOOKUP( VLOOKUP($A2,'[2]OSMEC ID + EVENT'!$A:$E,2,FALSE),Events!$B:$D,3,FALSE)) -> E001 | E2: =IF(E$1=Events!$A$3, VLOOKUP( VLOOKUP($A2,'[2]OSMEC ID + EVENT'!$A:$E,3,FALSE),Events!$B:$D,3,FALSE)) -> E002 | F2: =IF($F$1=Events!$A$4, VLOOKUP( VLOOKUP($A4,'[2]OSMEC ID + EVENT'!$A:$E,4,FALSE),Events!$B:$D,3,FALSE),) -> E003 | G2: =IF($G$1=Events!$A$5, VLOOKUP( VLOOKUP($A4,'[2]OSMEC ID + EVENT'!$A:$E,5,FALSE),Events!$B:$D,3,FALSE),) -> E004 | H2: =IF($H$1= VLOOKUP($H$1,Events!$A:$D,1,FALSE), VLOOKUP( VLOOKUP($A2,'[3]OSMEC ID + EVENT'!$A:$M,2,FALSE),Events!$B:$D,3,FALSE),) -> E005 | I2: =IF(I$1= VLOOKUP(I$1,Events!$A:$D,1,FALSE), VLOOKUP( VLOOKUP($A2,'[3]OSMEC ID + EVENT'!$A:$M,3,FALSE),Events!$B:$D,3,FALSE),) -> E006 | J2: =IF(J$1= VLOOKUP(J$1,Events!$A:$D,1,FALSE), VLOOKUP( VLOOKUP($A2,'[3]OSMEC ID + EVENT'!$A:$M,4,FALSE),Events!$B:$D,3,FALSE),) -> E007 | K2: =IF(K$1= VLOOKUP(K$1,Events!$A:$D,1,FALSE), VLOOKUP( VLOOKUP($A2,'[3]OSMEC ID + EVENT'!$A:$M,5,FALSE),Events!$B:$D,3,FALSE),) -> E008 | L2: =IF(L$1= VLOOKUP(L$1,Events!$A:$D,1,FALSE), VLOOKUP( VLOOKUP($A2,'[3]OSMEC ID + EVENT'!$A:$M,6,FALSE),Events!$B:$D,3,FALSE),) -> E009 | M2: =IF(M$1= VLOOKUP(M$1,Events!$A:$D,1,FALSE), VLOOKUP( VLOOKUP($A2,'[3]OSMEC ID + EVENT'!$A:$M,7,FALSE),Events!$B:$D,3,FALSE),) -> E010 | N2: =IF(N$1= VLOOKUP(N$1,Events!$A:$D,1,FALSE), VLOOKUP( VLOOKUP($A2,'[3]OSMEC ID + EVENT'!$A:$M,8,FALSE),Events!$B:$D,3,FALSE),) -> E011 | O2: =IF(O$1= VLOOKUP(O$1,Events!$A:$D,1,FALSE), VLOOKUP( VLOOKUP($A2,'[3]OSMEC ID + EVENT'!$A:$M,9,FALSE),Events!$B:$D,3,FALSE),) -> E012 | P2: =IF(P$1= VLOOKUP(P$1,Events!$A:$D,1,FALSE), VLOOKUP( VLOOKUP($A2,'[3]OSMEC ID + EVENT'!$A:$M,10,FALSE),Events!$B:$D,3,FALSE),) -> E013 | Q2: =IF(Q$1= VLOOKUP(Q$1,Events!$A:$D,1,FALSE), VLOOKUP( VLOOKUP($A2,'[3]OSMEC ID + EVENT'!$A:$M,11,FALSE),Events!$B:$D,3,FALSE),) -> E014 | R2: =IF(R$1= VLOOKUP(R$1,Events!$A:$D,1,FALSE), VLOOKUP( VLOOKUP($A2,'[3]OSMEC ID + EVENT'!$A:$M,12,FALSE),Events!$B:$D,3,FALSE),) -> E015 | S2: =IF(S$1= VLOOKUP(S$1,Events!$A:$D,1,FALSE), VLOOKUP( VLOOKUP($A2,'[3]OSMEC ID + EVENT'!$A:$M,13,FALSE),Events!$B:$D,3,FALSE),) -> E016 | T2: =IF(T$1= VLOOKUP(T$1,Events!$A:$D,1,FALSE), VLOOKUP( VLOOKUP($A2,'[4]OSMEC ID + EVENT'!$A:$I,2,FALSE),Events!$B:$D,3,FALSE),) -> E017 | U2: =IF( ISNA(MATCH(U$1,Events!$A:$A,0)), 0, VLOOKUP( VLOOKUP($A2,'[4]OSMEC ID + EVENT'!$A:$I,3,FALSE),Events!$B:$D,3,FALSE)) -> E018 | V2: =IF( ISNA(MATCH(V$1,Events!$A:$A,0)), 0, VLOOKUP( VLOOKUP($A2,'[4]OSMEC ID + EVENT'!$A:$I,4,FALSE),Events!$B:$D,3,FALSE)) -> E019 | W2: =IF( ISNA(MATCH(W$1,Events!$A:$A,0)), 0, VLOOKUP( VLOOKUP($A2,'[4]OSMEC ID + EVENT'!$A:$I,5,FALSE),Events!$B:$D,3,FALSE)) -> E020 | X2: =IF( ISNA(MATCH(X$1,Events!$A:$A,0)), 0, VLOOKUP( VLOOKUP($A2,'[4]OSMEC ID + EVENT'!$A:$I,6,FALSE),Events!$B:$D,3,FALSE)) -> E021 | Y2: =IF( ISNA(MATCH(Y$1,Events!$A:$A,0)), 0, VLOOKUP( VLOOKUP($A2,'[4]OSMEC ID + EVENT'!$A:$I,7,FALSE),Events!$B:$D,3,FALSE)) -> E022 | Z2: =IF( ISNA(MATCH(Z$1,Events!$A:$A,0)), 0, VLOOKUP( VLOOKUP($A2,'[4]OSMEC ID + EVENT'!$A:$I,8,FALSE),Events!$B:$D,3,FALSE)) -> E023 | AA2: =IFERROR( VLOOKUP( VLOOKUP(A2,'[5]OSMEC ID + SUBJECT'!$A:$B,2,FALSE),Subjects!$B:$D,3,FALSE),"") | AB2: =IFERROR( VLOOKUP( VLOOKUP(A2,'[6]OSMEC ID + SUBJECT'!$A:$B,2,FALSE),Subjects!B:D,3,FALSE),"") | AC2: =IFERROR( VLOOKUP( VLOOKUP(A2,'[7]OSMEC-ID + SESSION'!$A:$B,2,FALSE),Subjects!$B:$D,3,FALSE),"") | AD2: =IFERROR( VLOOKUP( VLOOKUP(A2,'[8]OSMEC ID + SESSION'!$A:$B,2,FALSE),Subjects!$B:$D,3,FALSE),"") | AE2: =IFERROR( VLOOKUP( VLOOKUP(A2,'[9]OSMEC ID + SUBJECT'!$A:$B,2,FALSE),Subjects!$B:$D,3,FALSE),"") | AF2: =IFERROR( VLOOKUP( VLOOKUP(A2,'[10]OSMEC ID + SESSION'!$A:$B,2,FALSE),Subjects!$B:$D,3),"")
A3: =Deligate_List!A3 -> OSMEC-0005 | B3: =VLOOKUP(A3,Deligate_List!A:B,2,FALSE) -> QAZI SYED ABDULLAH | C3: =IFERROR( VLOOKUP( VLOOKUP($A3,'[1]OSMEC ID + WORKSHOP'!$A:$B,2,FALSE),Workshop!A:C,3,FALSE),"") -> W002 | D3: =IF($D$1 =Events!$A$2, VLOOKUP( VLOOKUP($A3,'[2]OSMEC ID + EVENT'!$A:$E,2,FALSE),Events!$B:$D,3,FALSE)) -> E001 | E3: =IF(E$1=Events!$A$3, VLOOKUP( VLOOKUP($A3,'[2]OSMEC ID + EVENT'!$A:$E,3,FALSE),Events!B:D,3,FALSE)) -> E002 | F3: =IF($F$1=Events!$A$4, VLOOKUP( VLOOKUP($A5,'[2]OSMEC ID + EVENT'!$A:$E,4,FALSE),Events!B:D,3,FALSE),) -> E003 | G3: =IF($G$1=Events!$A$5, VLOOKUP( VLOOKUP($A5,'[2]OSMEC ID + EVENT'!$A:$E,5,FALSE),Events!$B:$D,3,FALSE),) -> E004 | H3: =IF($H$1= VLOOKUP($H$1,Events!$A:$D,1,FALSE), VLOOKUP( VLOOKUP(A3,'[3]OSMEC ID + EVENT'!$A:$M,2,FALSE),Events!B:D,3,FALSE),) -> E005 | I3: =IF(I$1= VLOOKUP(I$1,Events!$A:$D,1,FALSE), VLOOKUP( VLOOKUP($A3,'[3]OSMEC ID + EVENT'!$A:$M,3,FALSE),Events!$B:$D,3,FALSE),) -> E006 | J3: =IF(J$1= VLOOKUP(J$1,Events!$A:$D,1,FALSE), VLOOKUP( VLOOKUP($A3,'[3]OSMEC ID + EVENT'!$A:$M,4,FALSE),Events!$B:$D,3,FALSE),) -> E007 | K3: =IF(K$1= VLOOKUP(K$1,Events!$A:$D,1,FALSE), VLOOKUP( VLOOKUP($A3,'[3]OSMEC ID + EVENT'!$A:$M,5,FALSE),Events!$B:$D,3,FALSE),) -> E008 | L3: =IF(L$1= VLOOKUP(L$1,Events!$A:$D,1,FALSE), VLOOKUP( VLOOKUP($A3,'[3]OSMEC ID + EVENT'!$A:$M,6,FALSE),Events!$B:$D,3,FALSE),) -> E009 | M3: =IF(M$1= VLOOKUP(M$1,Events!$A:$D,1,FALSE), VLOOKUP( VLOOKUP($A3,'[3]OSMEC ID + EVENT'!$A:$M,7,FALSE),Events!$B:$D,3,FALSE),) -> E010 | N3: =IF(N$1= VLOOKUP(N$1,Events!$A:$D,1,FALSE), VLOOKUP( VLOOKUP($A3,'[3]OSMEC ID + EVENT'!$A:$M,8,FALSE),Events!$B:$D,3,FALSE),) -> E011 | O3: =IF(O$1= VLOOKUP(O$1,Events!$A:$D,1,FALSE), VLOOKUP( VLOOKUP($A3,'[3]OSMEC ID + EVENT'!$A:$M,9,FALSE),Events!$B:$D,3,FALSE),) -> E012 | P3: =IF(P$1= VLOOKUP(P$1,Events!$A:$D,1,FALSE), VLOOKUP( VLOOKUP($A3,'[3]OSMEC ID + EVENT'!$A:$M,10,FALSE),Events!$B:$D,3,FALSE),) -> E013 | Q3: =IF(Q$1= VLOOKUP(Q$1,Events!$A:$D,1,FALSE), VLOOKUP( VLOOKUP($A3,'[3]OSMEC ID + EVENT'!$A:$M,11,FALSE),Events!$B:$D,3,FALSE),) -> E014 | R3: =IF(R$1= VLOOKUP(R$1,Events!$A:$D,1,FALSE), VLOOKUP( VLOOKUP($A3,'[3]OSMEC ID + EVENT'!$A:$M,12,FALSE),Events!$B:$D,3,FALSE),) -> E015 | S3: =IF(S$1= VLOOKUP(S$1,Events!$A:$D,1,FALSE), VLOOKUP( VLOOKUP($A3,'[3]OSMEC ID + EVENT'!$A:$M,13,FALSE),Events!$B:$D,3,FALSE),) -> E016 | T3: =IF( ISNA(MATCH(T$1,Events!$A:$A,0)), 0, VLOOKUP( VLOOKUP(A3,'[4]OSMEC ID + EVENT'!$A:$I,2,FALSE),Events!$B:$D,3,FALSE)) -> E017 | U3: =IF( ISNA(MATCH(U$1,Events!$A:$A,0)), 0, VLOOKUP( VLOOKUP($A3,'[4]OSMEC ID + EVENT'!$A:$I,3,FALSE),Events!$B:$D,3,FALSE)) -> E018 | V3: =IF( ISNA(MATCH(V$1,Events!$A:$A,0)), 0, VLOOKUP( VLOOKUP($A3,'[4]OSMEC ID + EVENT'!$A:$I,4,FALSE),Events!$B:$D,3,FALSE)) -> E019 | W3: =IF( ISNA(MATCH(W$1,Events!$A:$A,0)), 0, VLOOKUP( VLOOKUP($A3,'[4]OSMEC ID + EVENT'!$A:$I,5,FALSE),Events!$B:$D,3,FALSE)) -> E020 | X3: =IF( ISNA(MATCH(X$1,Events!$A:$A,0)), 0, VLOOKUP( VLOOKUP($A3,'[4]OSMEC ID + EVENT'!$A:$I,6,FALSE),Events!$B:$D,3,FALSE)) -> E021 | Y3: =IF( ISNA(MATCH(Y$1,Events!$A:$A,0)), 0, VLOOKUP( VLOOKUP($A3,'[4]OSMEC ID + EVENT'!$A:$I,7,FALSE),Events!$B:$D,3,FALSE)) -> E022 | Z3: =IF( ISNA(MATCH(Z$1,Events!$A:$A,0)), 0, VLOOKUP( VLOOKUP($A3,'[4]OSMEC ID + EVENT'!$A:$I,8,FALSE),Events!$B:$D,3,FALSE)) -> E023 | AA3: =IFERROR( VLOOKUP( VLOOKUP(A3,'[5]OSMEC ID + SUBJECT'!$A:$B,2,FALSE),Subjects!$B:$D,3,FALSE),"") | AB3: =IFERROR( VLOOKUP( VLOOKUP(A3,'[6]OSMEC ID + SUBJECT'!$A:$B,2,FALSE),Subjects!B:D,3,FALSE),"") -> S006 | AC3: =IFERROR( VLOOKUP( VLOOKUP(A3,'[7]OSMEC-ID + SESSION'!$A:$B,2,FALSE),Subjects!$B:$D,3,FALSE),"") | AD3: =IFERROR( VLOOKUP( VLOOKUP(A3,'[8]OSMEC ID + SESSION'!$A:$B,2,FALSE),Subjects!$B:$D,3,FALSE),"") | AE3: =IFERROR( VLOOKUP( VLOOKUP(A3,'[9]OSMEC ID + SUBJECT'!$A:$B,2,FALSE),Subjects!$B:$D,3,FALSE),"") | AF3: =IFERROR( VLOOKUP( VLOOKUP(A3,'[10]OSMEC ID + SESSION'!$A:$B,2,FALSE),Subjects!$B:$D,3),"")
A4: =Deligate_List!A4 -> OSMEC-0025 | B4: =VLOOKUP(A4,Deligate_List!A:B,2,FALSE) -> VULUVAPALLE SUROHAN REDDY | C4: =IFERROR( VLOOKUP( VLOOKUP($A4,'[1]OSMEC ID + WORKSHOP'!$A:$B,2,FALSE),Workshop!A:C,3,FALSE),"") -> W012 | D4: =IF($D$1 =Events!$A$2, VLOOKUP( VLOOKUP($A4,'[2]OSMEC ID + EVENT'!$A:$E,2,FALSE),Events!$B:$D,3,FALSE)) -> E001 | E4: =IF(E$1=Events!$A$3, VLOOKUP( VLOOKUP($A4,'[2]OSMEC ID + EVENT'!$A:$E,3,FALSE),Events!B:D,3,FALSE)) -> E002 | F4: =IF($F$1=Events!$A$4, VLOOKUP( VLOOKUP($A6,'[2]OSMEC ID + EVENT'!$A:$E,4,FALSE),Events!B:D,3,FALSE),) -> E003 | G4: =IF($G$1=Events!$A$5, VLOOKUP( VLOOKUP($A6,'[2]OSMEC ID + EVENT'!$A:$E,5,FALSE),Events!$B:$D,3,FALSE),) -> E004 | H4: =IF($H$1= VLOOKUP($H$1,Events!$A:$D,1,FALSE), VLOOKUP( VLOOKUP(A4,'[3]OSMEC ID + EVENT'!$A:$M,2,FALSE),Events!B:D,3,FALSE),) -> E005 | I4: =IF(I$1= VLOOKUP(I$1,Events!$A:$D,1,FALSE), VLOOKUP( VLOOKUP($A4,'[3]OSMEC ID + EVENT'!$A:$M,3,FALSE),Events!$B:$D,3,FALSE),) -> E006 | J4: =IF(J$1= VLOOKUP(J$1,Events!$A:$D,1,FALSE), VLOOKUP( VLOOKUP($A4,'[3]OSMEC ID + EVENT'!$A:$M,4,FALSE),Events!$B:$D,3,FALSE),) -> E007 | K4: =IF(K$1= VLOOKUP(K$1,Events!$A:$D,1,FALSE), VLOOKUP( VLOOKUP($A4,'[3]OSMEC ID + EVENT'!$A:$M,5,FALSE),Events!$B:$D,3,FALSE),) -> E008 | L4: =IF(L$1= VLOOKUP(L$1,Events!$A:$D,1,FALSE), VLOOKUP( VLOOKUP($A4,'[3]OSMEC ID + EVENT'!$A:$M,6,FALSE),Events!$B:$D,3,FALSE),) -> E009 | M4: =IF(M$1= VLOOKUP(M$1,Events!$A:$D,1,FALSE), VLOOKUP( VLOOKUP($A4,'[3]OSMEC ID + EVENT'!$A:$M,7,FALSE),Events!$B:$D,3,FALSE),) -> E010 | N4: =IF(N$1= VLOOKUP(N$1,Events!$A:$D,1,FALSE), VLOOKUP( VLOOKUP($A4,'[3]OSMEC ID + EVENT'!$A:$M,8,FALSE),Events!$B:$D,3,FALSE),) -> E011 | O4: =IF(O$1= VLOOKUP(O$1,Events!$A:$D,1,FALSE), VLOOKUP( VLOOKUP($A4,'[3]OSMEC ID + EVENT'!$A:$M,9,FALSE),Events!$B:$D,3,FALSE),) -> E012 | P4: =IF(P$1= VLOOKUP(P$1,Events!$A:$D,1,FALSE), VLOOKUP( VLOOKUP($A4,'[3]OSMEC ID + EVENT'!$A:$M,10,FALSE),Events!$B:$D,3,FALSE),) -> E013 | Q4: =IF(Q$1= VLOOKUP(Q$1,Events!$A:$D,1,FALSE), VLOOKUP( VLOOKUP($A4,'[3]OSMEC ID + EVENT'!$A:$M,11,FALSE),Events!$B:$D,3,FALSE),) -> E014 | R4: =IF(R$1= VLOOKUP(R$1,Events!$A:$D,1,FALSE), VLOOKUP( VLOOKUP($A4,'[3]OSMEC ID + EVENT'!$A:$M,12,FALSE),Events!$B:$D,3,FALSE),) -> E015 | S4: =IF(S$1= VLOOKUP(S$1,Events!$A:$D,1,FALSE), VLOOKUP( VLOOKUP($A4,'[3]OSMEC ID + EVENT'!$A:$M,13,FALSE),Events!$B:$D,3,FALSE),) -> E016 | T4: =IF( ISNA(MATCH(T$1,Events!$A:$A,0)), 0, VLOOKUP( VLOOKUP(A4,'[4]OSMEC ID + EVENT'!$A:$I,2,FALSE),Events!$B:$D,3,FALSE)) -> E017 | U4: =IF( ISNA(MATCH(U$1,Events!$A:$A,0)), 0, VLOOKUP( VLOOKUP($A4,'[4]OSMEC ID + EVENT'!$A:$I,3,FALSE),Events!$B:$D,3,FALSE)) -> E018 | V4: =IF( ISNA(MATCH(V$1,Events!$A:$A,0)), 0, VLOOKUP( VLOOKUP($A4,'[4]OSMEC ID + EVENT'!$A:$I,4,FALSE),Events!$B:$D,3,FALSE)) -> E019 | W4: =IF( ISNA(MATCH(W$1,Events!$A:$A,0)), 0, VLOOKUP( VLOOKUP($A4,'[4]OSMEC ID + EVENT'!$A:$I,5,FALSE),Events!$B:$D,3,FALSE)) -> E020 | X4: =IF( ISNA(MATCH(X$1,Events!$A:$A,0)), 0, VLOOKUP( VLOOKUP($A4,'[4]OSMEC ID + EVENT'!$A:$I,6,FALSE),Events!$B:$D,3,FALSE)) -> E021 | Y4: =IF( ISNA(MATCH(Y$1,Events!$A:$A,0)), 0, VLOOKUP( VLOOKUP($A4,'[4]OSMEC ID + EVENT'!$A:$I,7,FALSE),Events!$B:$D,3,FALSE)) -> E022 | Z4: =IF( ISNA(MATCH(Z$1,Events!$A:$A,0)), 0, VLOOKUP( VLOOKUP($A4,'[4]OSMEC ID + EVENT'!$A:$I,8,FALSE),Events!$B:$D,3,FALSE)) -> E023 | AA4: =IFERROR( VLOOKUP( VLOOKUP(A4,'[5]OSMEC ID + SUBJECT'!$A:$B,2,FALSE),Subjects!$B:$D,3,FALSE),"") | AB4: =IFERROR( VLOOKUP( VLOOKUP(A4,'[6]OSMEC ID + SUBJECT'!$A:$B,2,FALSE),Subjects!B:D,3,FALSE),"") | AC4: =IFERROR( VLOOKUP( VLOOKUP(A4,'[7]OSMEC-ID + SESSION'!$A:$B,2,FALSE),Subjects!$B:$D,3,FALSE),"") | AD4: =IFERROR( VLOOKUP( VLOOKUP(A4,'[8]OSMEC ID + SESSION'!$A:$B,2,FALSE),Subjects!$B:$D,3,FALSE),"") | AE4: =IFERROR( VLOOKUP( VLOOKUP(A4,'[9]OSMEC ID + SUBJECT'!$A:$B,2,FALSE),Subjects!$B:$D,3,FALSE),"") | AF4: =IFERROR( VLOOKUP( VLOOKUP(A4,'[10]OSMEC ID + SESSION'!$A:$B,2,FALSE),Subjects!$B:$D,3),"")
A5: =Deligate_List!A5 -> OSMEC-0006 | B5: =VLOOKUP(A5,Deligate_List!A:B,2,FALSE) -> Diya s bhandary | C5: =IFERROR( VLOOKUP( VLOOKUP($A5,'[1]OSMEC ID + WORKSHOP'!$A:$B,2,FALSE),Workshop!A:C,3,FALSE),"") -> W008 | D5: =IF($D$1 =Events!$A$2, VLOOKUP( VLOOKUP($A5,'[2]OSMEC ID + EVENT'!$A:$E,2,FALSE),Events!$B:$D,3,FALSE)) -> E001 | E5: =IF(E$1=Events!$A$3, VLOOKUP( VLOOKUP($A5,'[2]OSMEC ID + EVENT'!$A:$E,3,FALSE),Events!B:D,3,FALSE)) -> E002 | F5: =IF($F$1=Events!$A$4, VLOOKUP( VLOOKUP($A7,'[2]OSMEC ID + EVENT'!$A:$E,4,FALSE),Events!B:D,3,FALSE),) -> E003 | G5: =IF($G$1=Events!$A$5, VLOOKUP( VLOOKUP($A7,'[2]OSMEC ID + EVENT'!$A:$E,5,FALSE),Events!$B:$D,3,FALSE),) -> E004 | H5: =IF($H$1= VLOOKUP($H$1,Events!$A:$D,1,FALSE), VLOOKUP( VLOOKUP(A5,'[3]OSMEC ID + EVENT'!$A:$M,2,FALSE),Events!B:D,3,FALSE),) -> E005 | I5: =IF(I$1= VLOOKUP(I$1,Events!$A:$D,1,FALSE), VLOOKUP( VLOOKUP($A5,'[3]OSMEC ID + EVENT'!$A:$M,3,FALSE),Events!$B:$D,3,FALSE),) -> E006 | J5: =IF(J$1= VLOOKUP(J$1,Events!$A:$D,1,FALSE), VLOOKUP( VLOOKUP($A5,'[3]OSMEC ID + EVENT'!$A:$M,4,FALSE),Events!$B:$D,3,FALSE),) -> E007 | K5: =IF(K$1= VLOOKUP(K$1,Events!$A:$D,1,FALSE), VLOOKUP( VLOOKUP($A5,'[3]OSMEC ID + EVENT'!$A:$M,5,FALSE),Events!$B:$D,3,FALSE),) -> E008 | L5: =IF(L$1= VLOOKUP(L$1,Events!$A:$D,1,FALSE), VLOOKUP( VLOOKUP($A5,'[3]OSMEC ID + EVENT'!$A:$M,6,FALSE),Events!$B:$D,3,FALSE),) -> E009 | M5: =IF(M$1= VLOOKUP(M$1,Events!$A:$D,1,FALSE), VLOOKUP( VLOOKUP($A5,'[3]OSMEC ID + EVENT'!$A:$M,7,FALSE),Events!$B:$D,3,FALSE),) -> E010 | N5: =IF(N$1= VLOOKUP(N$1,Events!$A:$D,1,FALSE), VLOOKUP( VLOOKUP($A5,'[3]OSMEC ID + EVENT'!$A:$M,8,FALSE),Events!$B:$D,3,FALSE),) -> E011 | O5: =IF(O$1= VLOOKUP(O$1,Events!$A:$D,1,FALSE), VLOOKUP( VLOOKUP($A5,'[3]OSMEC ID + EVENT'!$A:$M,9,FALSE),Events!$B:$D,3,FALSE),) -> E012 | P5: =IF(P$1= VLOOKUP(P$1,Events!$A:$D,1,FALSE), VLOOKUP( VLOOKUP($A5,'[3]OSMEC ID + EVENT'!$A:$M,10,FALSE),Events!$B:$D,3,FALSE),) -> E013 | Q5: =IF(Q$1= VLOOKUP(Q$1,Events!$A:$D,1,FALSE), VLOOKUP( VLOOKUP($A5,'[3]OSMEC ID + EVENT'!$A:$M,11,FALSE),Events!$B:$D,3,FALSE),) -> E014 | R5: =IF(R$1= VLOOKUP(R$1,Events!$A:$D,1,FALSE), VLOOKUP( VLOOKUP($A5,'[3]OSMEC ID + EVENT'!$A:$M,12,FALSE),Events!$B:$D,3,FALSE),) -> E015 | S5: =IF(S$1= VLOOKUP(S$1,Events!$A:$D,1,FALSE), VLOOKUP( VLOOKUP($A5,'[3]OSMEC ID + EVENT'!$A:$M,13,FALSE),Events!$B:$D,3,FALSE),) -> E016 | T5: =IF( ISNA(MATCH(T$1,Events!$A:$A,0)), 0, VLOOKUP( VLOOKUP(A5,'[4]OSMEC ID + EVENT'!$A:$I,2,FALSE),Events!$B:$D,3,FALSE)) -> E017 | U5: =IF( ISNA(MATCH(U$1,Events!$A:$A,0)), 0, VLOOKUP( VLOOKUP($A5,'[4]OSMEC ID + EVENT'!$A:$I,3,FALSE),Events!$B:$D,3,FALSE)) -> E018 | V5: =IF( ISNA(MATCH(V$1,Events!$A:$A,0)), 0, VLOOKUP( VLOOKUP($A5,'[4]OSMEC ID + EVENT'!$A:$I,4,FALSE),Events!$B:$D,3,FALSE)) -> E019 | W5: =IF( ISNA(MATCH(W$1,Events!$A:$A,0)), 0, VLOOKUP( VLOOKUP($A5,'[4]OSMEC ID + EVENT'!$A:$I,5,FALSE),Events!$B:$D,3,FALSE)) -> E020 | X5: =IF( ISNA(MATCH(X$1,Events!$A:$A,0)), 0, VLOOKUP( VLOOKUP($A5,'[4]OSMEC ID + EVENT'!$A:$I,6,FALSE),Events!$B:$D,3,FALSE)) -> E021 | Y5: =IF( ISNA(MATCH(Y$1,Events!$A:$A,0)), 0, VLOOKUP( VLOOKUP($A5,'[4]OSMEC ID + EVENT'!$A:$I,7,FALSE),Events!$B:$D,3,FALSE)) -> E022 | Z5: =IF( ISNA(MATCH(Z$1,Events!$A:$A,0)), 0, VLOOKUP( VLOOKUP($A5,'[4]OSMEC ID + EVENT'!$A:$I,8,FALSE),Events!$B:$D,3,FALSE)) -> E023 | AA5: =IFERROR( VLOOKUP( VLOOKUP(A5,'[5]OSMEC ID + SUBJECT'!$A:$B,2,FALSE),Subjects!$B:$D,3,FALSE),"") | AB5: =IFERROR( VLOOKUP( VLOOKUP(A5,'[6]OSMEC ID + SUBJECT'!$A:$B,2,FALSE),Subjects!B:D,3,FALSE),"") | AC5: =IFERROR( VLOOKUP( VLOOKUP(A5,'[7]OSMEC-ID + SESSION'!$A:$B,2,FALSE),Subjects!$B:$D,3,FALSE),"") | AD5: =IFERROR( VLOOKUP( VLOOKUP(A5,'[8]OSMEC ID + SESSION'!$A:$B,2,FALSE),Subjects!$B:$D,3,FALSE),"") | AE5: =IFERROR( VLOOKUP( VLOOKUP(A5,'[9]OSMEC ID + SUBJECT'!$A:$B,2,FALSE),Subjects!$B:$D,3,FALSE),"") | AF5: =IFERROR( VLOOKUP( VLOOKUP(A5,'[10]OSMEC ID + SESSION'!$A:$B,2,FALSE),Subjects!$B:$D,3),"")
A6: =Deligate_List!A6 -> OSMEC-0009 | B6: =VLOOKUP(A6,Deligate_List!A:B,2,FALSE) -> S SADAF SUHANA AFROZE | C6: =IFERROR( VLOOKUP( VLOOKUP($A6,'[1]OSMEC ID + WORKSHOP'!$A:$B,2,FALSE),Workshop!A:C,3,FALSE),"") | D6: =IF($D$1 =Events!$A$2, VLOOKUP( VLOOKUP($A6,'[2]OSMEC ID + EVENT'!$A:$E,2,FALSE),Events!$B:$D,3,FALSE)) -> E001 | E6: =IF(E$1=Events!$A$3, VLOOKUP( VLOOKUP($A6,'[2]OSMEC ID + EVENT'!$A:$E,3,FALSE),Events!B:D,3,FALSE)) -> E002 | F6: =IF($F$1=Events!$A$4, VLOOKUP( VLOOKUP($A8,'[2]OSMEC ID + EVENT'!$A:$E,4,FALSE),Events!B:D,3,FALSE),) -> E003 | G6: =IF($G$1=Events!$A$5, VLOOKUP( VLOOKUP($A8,'[2]OSMEC ID + EVENT'!$A:$E,5,FALSE),Events!$B:$D,3,FALSE),) -> E004 | H6: =IF($H$1= VLOOKUP($H$1,Events!$A:$D,1,FALSE), VLOOKUP( VLOOKUP(A6,'[3]OSMEC ID + EVENT'!$A:$M,2,FALSE),Events!B:D,3,FALSE),) -> E005 | I6: =IF(I$1= VLOOKUP(I$1,Events!$A:$D,1,FALSE), VLOOKUP( VLOOKUP($A6,'[3]OSMEC ID + EVENT'!$A:$M,3,FALSE),Events!$B:$D,3,FALSE),) -> E006 | J6: =IF(J$1= VLOOKUP(J$1,Events!$A:$D,1,FALSE), VLOOKUP( VLOOKUP($A6,'[3]OSMEC ID + EVENT'!$A:$M,4,FALSE),Events!$B:$D,3,FALSE),) -> E007 | K6: =IF(K$1= VLOOKUP(K$1,Events!$A:$D,1,FALSE), VLOOKUP( VLOOKUP($A6,'[3]OSMEC ID + EVENT'!$A:$M,5,FALSE),Events!$B:$D,3,FALSE),) -> E008 | L6: =IF(L$1= VLOOKUP(L$1,Events!$A:$D,1,FALSE), VLOOKUP( VLOOKUP($A6,'[3]OSMEC ID + EVENT'!$A:$M,6,FALSE),Events!$B:$D,3,FALSE),) -> E009 | M6: =IF(M$1= VLOOKUP(M$1,Events!$A:$D,1,FALSE), VLOOKUP( VLOOKUP($A6,'[3]OSMEC ID + EVENT'!$A:$M,7,FALSE),Events!$B:$D,3,FALSE),) -> E010 | N6: =IF(N$1= VLOOKUP(N$1,Events!$A:$D,1,FALSE), VLOOKUP( VLOOKUP($A6,'[3]OSMEC ID + EVENT'!$A:$M,8,FALSE),Events!$B:$D,3,FALSE),) -> E011 | O6: =IF(O$1= VLOOKUP(O$1,Events!$A:$D,1,FALSE), VLOOKUP( VLOOKUP($A6,'[3]OSMEC ID + EVENT'!$A:$M,9,FALSE),Events!$B:$D,3,FALSE),) -> E012 | P6: =IF(P$1= VLOOKUP(P$1,Events!$A:$D,1,FALSE), VLOOKUP( VLOOKUP($A6,'[3]OSMEC ID + EVENT'!$A:$M,10,FALSE),Events!$B:$D,3,FALSE),) -> E013 | Q6: =IF(Q$1= VLOOKUP(Q$1,Events!$A:$D,1,FALSE), VLOOKUP( VLOOKUP($A6,'[3]OSMEC ID + EVENT'!$A:$M,11,FALSE),Events!$B:$D,3,FALSE),) -> E014 | R6: =IF(R$1= VLOOKUP(R$1,Events!$A:$D,1,FALSE), VLOOKUP( VLOOKUP($A6,'[3]OSMEC ID + EVENT'!$A:$M,12,FALSE),Events!$B:$D,3,FALSE),) -> E015 | S6: =IF(S$1= VLOOKUP(S$1,Events!$A:$D,1,FALSE), VLOOKUP( VLOOKUP($A6,'[3]OSMEC ID + EVENT'!$A:$M,13,FALSE),Events!$B:$D,3,FALSE),) -> E016 | T6: =IF( ISNA(MATCH(T$1,Events!$A:$A,0)), 0, VLOOKUP( VLOOKUP(A6,'[4]OSMEC ID + EVENT'!$A:$I,2,FALSE),Events!$B:$D,3,FALSE)) -> E017 | U6: =IF( ISNA(MATCH(U$1,Events!$A:$A,0)), 0, VLOOKUP( VLOOKUP($A6,'[4]OSMEC ID + EVENT'!$A:$I,3,FALSE),Events!$B:$D,3,FALSE)) -> E018 | V6: =IF( ISNA(MATCH(V$1,Events!$A:$A,0)), 0, VLOOKUP( VLOOKUP($A6,'[4]OSMEC ID + EVENT'!$A:$I,4,FALSE),Events!$B:$D,3,FALSE)) -> E019 | W6: =IF( ISNA(MATCH(W$1,Events!$A:$A,0)), 0, VLOOKUP( VLOOKUP($A6,'[4]OSMEC ID + EVENT'!$A:$I,5,FALSE),Events!$B:$D,3,FALSE)) -> E020 | X6: =IF( ISNA(MATCH(X$1,Events!$A:$A,0)), 0, VLOOKUP( VLOOKUP($A6,'[4]OSMEC ID + EVENT'!$A:$I,6,FALSE),Events!$B:$D,3,FALSE)) -> E021 | Y6: =IF( ISNA(MATCH(Y$1,Events!$A:$A,0)), 0, VLOOKUP( VLOOKUP($A6,'[4]OSMEC ID + EVENT'!$A:$I,7,FALSE),Events!$B:$D,3,FALSE)) -> E022 | Z6: =IF( ISNA(MATCH(Z$1,Events!$A:$A,0)), 0, VLOOKUP( VLOOKUP($A6,'[4]OSMEC ID + EVENT'!$A:$I,8,FALSE),Events!$B:$D,3,FALSE)) -> E023 | AA6: =IFERROR( VLOOKUP( VLOOKUP(A6,'[5]OSMEC ID + SUBJECT'!$A:$B,2,FALSE),Subjects!$B:$D,3,FALSE),"") | AB6: =IFERROR( VLOOKUP( VLOOKUP(A6,'[6]OSMEC ID + SUBJECT'!$A:$B,2,FALSE),Subjects!B:D,3,FALSE),"") | AC6: =IFERROR( VLOOKUP( VLOOKUP(A6,'[7]OSMEC-ID + SESSION'!$A:$B,2,FALSE),Subjects!$B:$D,3,FALSE),"") | AD6: =IFERROR( VLOOKUP( VLOOKUP(A6,'[8]OSMEC ID + SESSION'!$A:$B,2,FALSE),Subjects!$B:$D,3,FALSE),"") | AE6: =IFERROR( VLOOKUP( VLOOKUP(A6,'[9]OSMEC ID + SUBJECT'!$A:$B,2,FALSE),Subjects!$B:$D,3,FALSE),"") | AF6: =IFERROR( VLOOKUP( VLOOKUP(A6,'[10]OSMEC ID + SESSION'!$A:$B,2,FALSE),Subjects!$B:$D,3),"")
A7: =Deligate_List!A7 -> OSMEC-0007 | B7: =VLOOKUP(A7,Deligate_List!A:B,2,FALSE) -> Nithin Kumar Punia | C7: =IFERROR( VLOOKUP( VLOOKUP($A7,'[1]OSMEC ID + WORKSHOP'!$A:$B,2,FALSE),Workshop!A:C,3,FALSE),"") -> W005 | D7: =IF($D$1 =Events!$A$2, VLOOKUP( VLOOKUP($A7,'[2]OSMEC ID + EVENT'!$A:$E,2,FALSE),Events!$B:$D,3,FALSE)) -> E001 | E7: =IF(E$1=Events!$A$3, VLOOKUP( VLOOKUP($A7,'[2]OSMEC ID + EVENT'!$A:$E,3,FALSE),Events!B:D,3,FALSE)) -> E002 | F7: =IF($F$1=Events!$A$4, VLOOKUP( VLOOKUP($A9,'[2]OSMEC ID + EVENT'!$A:$E,4,FALSE),Events!B:D,3,FALSE),) -> E003 | G7: =IF($G$1=Events!$A$5, VLOOKUP( VLOOKUP($A9,'[2]OSMEC ID + EVENT'!$A:$E,5,FALSE),Events!$B:$D,3,FALSE),) -> E004 | H7: =IF($H$1= VLOOKUP($H$1,Events!$A:$D,1,FALSE), VLOOKUP( VLOOKUP(A7,'[3]OSMEC ID + EVENT'!$A:$M,2,FALSE),Events!B:D,3,FALSE),) -> E005 | I7: =IF(I$1= VLOOKUP(I$1,Events!$A:$D,1,FALSE), VLOOKUP( VLOOKUP($A7,'[3]OSMEC ID + EVENT'!$A:$M,3,FALSE),Events!$B:$D,3,FALSE),) -> E006 | J7: =IF(J$1= VLOOKUP(J$1,Events!$A:$D,1,FALSE), VLOOKUP( VLOOKUP($A7,'[3]OSMEC ID + EVENT'!$A:$M,4,FALSE),Events!$B:$D,3,FALSE),) -> E007 | K7: =IF(K$1= VLOOKUP(K$1,Events!$A:$D,1,FALSE), VLOOKUP( VLOOKUP($A7,'[3]OSMEC ID + EVENT'!$A:$M,5,FALSE),Events!$B:$D,3,FALSE),) -> E008 | L7: =IF(L$1= VLOOKUP(L$1,Events!$A:$D,1,FALSE), VLOOKUP( VLOOKUP($A7,'[3]OSMEC ID + EVENT'!$A:$M,6,FALSE),Events!$B:$D,3,FALSE),) -> E009 | M7: =IF(M$1= VLOOKUP(M$1,Events!$A:$D,1,FALSE), VLOOKUP( VLOOKUP($A7,'[3]OSMEC ID + EVENT'!$A:$M,7,FALSE),Events!$B:$D,3,FALSE),) -> E010 | N7: =IF(N$1= VLOOKUP(N$1,Events!$A:$D,1,FALSE), VLOOKUP( VLOOKUP($A7,'[3]OSMEC ID + EVENT'!$A:$M,8,FALSE),Events!$B:$D,3,FALSE),) -> E011 | O7: =IF(O$1= VLOOKUP(O$1,Events!$A:$D,1,FALSE), VLOOKUP( VLOOKUP($A7,'[3]OSMEC ID + EVENT'!$A:$M,9,FALSE),Events!$B:$D,3,FALSE),) -> E012 | P7: =IF(P$1= VLOOKUP(P$1,Events!$A:$D,1,FALSE), VLOOKUP( VLOOKUP($A7,'[3]OSMEC ID + EVENT'!$A:$M,10,FALSE),Events!$B:$D,3,FALSE),) -> E013 | Q7: =IF(Q$1= VLOOKUP(Q$1,Events!$A:$D,1,FALSE), VLOOKUP( VLOOKUP($A7,'[3]OSMEC ID + EVENT'!$A:$M,11,FALSE),Events!$B:$D,3,FALSE),) -> E014 | R7: =IF(R$1= VLOOKUP(R$1,Events!$A:$D,1,FALSE), VLOOKUP( VLOOKUP($A7,'[3]OSMEC ID + EVENT'!$A:$M,12,FALSE),Events!$B:$D,3,FALSE),) -> E015 | S7: =IF(S$1= VLOOKUP(S$1,Events!$A:$D,1,FALSE), VLOOKUP( VLOOKUP($A7,'[3]OSMEC ID + EVENT'!$A:$M,13,FALSE),Events!$B:$D,3,FALSE),) -> E016 | T7: =IF( ISNA(MATCH(T$1,Events!$A:$A,0)), 0, VLOOKUP( VLOOKUP(A7,'[4]OSMEC ID + EVENT'!$A:$I,2,FALSE),Events!$B:$D,3,FALSE)) -> E017 | U7: =IF( ISNA(MATCH(U$1,Events!$A:$A,0)), 0, VLOOKUP( VLOOKUP($A7,'[4]OSMEC ID + EVENT'!$A:$I,3,FALSE),Events!$B:$D,3,FALSE)) -> E018 | V7: =IF( ISNA(MATCH(V$1,Events!$A:$A,0)), 0, VLOOKUP( VLOOKUP($A7,'[4]OSMEC ID + EVENT'!$A:$I,4,FALSE),Events!$B:$D,3,FALSE)) -> E019 | W7: =IF( ISNA(MATCH(W$1,Events!$A:$A,0)), 0, VLOOKUP( VLOOKUP($A7,'[4]OSMEC ID + EVENT'!$A:$I,5,FALSE),Events!$B:$D,3,FALSE)) -> E020 | X7: =IF( ISNA(MATCH(X$1,Events!$A:$A,0)), 0, VLOOKUP( VLOOKUP($A7,'[4]OSMEC ID + EVENT'!$A:$I,6,FALSE),Events!$B:$D,3,FALSE)) -> E021 | Y7: =IF( ISNA(MATCH(Y$1,Events!$A:$A,0)), 0, VLOOKUP( VLOOKUP($A7,'[4]OSMEC ID + EVENT'!$A:$I,7,FALSE),Events!$B:$D,3,FALSE)) -> E022 | Z7: =IF( ISNA(MATCH(Z$1,Events!$A:$A,0)), 0, VLOOKUP( VLOOKUP($A7,'[4]OSMEC ID + EVENT'!$A:$I,8,FALSE),Events!$B:$D,3,FALSE)) -> E023 | AA7: =IFERROR( VLOOKUP( VLOOKUP(A7,'[5]OSMEC ID + SUBJECT'!$A:$B,2,FALSE),Subjects!$B:$D,3,FALSE),"") | AB7: =IFERROR( VLOOKUP( VLOOKUP(A7,'[6]OSMEC ID + SUBJECT'!$A:$B,2,FALSE),Subjects!B:D,3,FALSE),"") -> S007 | AC7: =IFERROR( VLOOKUP( VLOOKUP(A7,'[7]OSMEC-ID + SESSION'!$A:$B,2,FALSE),Subjects!$B:$D,3,FALSE),"") | AD7: =IFERROR( VLOOKUP( VLOOKUP(A7,'[8]OSMEC ID + SESSION'!$A:$B,2,FALSE),Subjects!$B:$D,3,FALSE),"") | AE7: =IFERROR( VLOOKUP( VLOOKUP(A7,'[9]OSMEC ID + SUBJECT'!$A:$B,2,FALSE),Subjects!$B:$D,3,FALSE),"") | AF7: =IFERROR( VLOOKUP( VLOOKUP(A7,'[10]OSMEC ID + SESSION'!$A:$B,2,FALSE),Subjects!$B:$D,3),"")
A8: =Deligate_List!A8 -> OSMEC-0016 | B8: =VLOOKUP(A8,Deligate_List!A:B,2,FALSE) -> Sri Sanjana Gunturi | C8: =IFERROR( VLOOKUP( VLOOKUP($A8,'[1]OSMEC ID + WORKSHOP'!$A:$B,2,FALSE),Workshop!A:C,3,FALSE),"") | D8: =IF($D$1 =Events!$A$2, VLOOKUP( VLOOKUP($A8,'[2]OSMEC ID + EVENT'!$A:$E,2,FALSE),Events!$B:$D,3,FALSE)) -> E001 | E8: =IF(E$1=Events!$A$3, VLOOKUP( VLOOKUP($A8,'[2]OSMEC ID + EVENT'!$A:$E,3,FALSE),Events!B:D,3,FALSE)) -> E002 | F8: =IF($F$1=Events!$A$4, VLOOKUP( VLOOKUP($A10,'[2]OSMEC ID + EVENT'!$A:$E,4,FALSE),Events!B:D,3,FALSE),) -> E003 | G8: =IF($G$1=Events!$A$5, VLOOKUP( VLOOKUP($A10,'[2]OSMEC ID + EVENT'!$A:$E,5,FALSE),Events!$B:$D,3,FALSE),) -> E004 | H8: =IF($H$1= VLOOKUP($H$1,Events!$A:$D,1,FALSE), VLOOKUP( VLOOKUP(A8,'[3]OSMEC ID + EVENT'!$A:$M,2,FALSE),Events!B:D,3,FALSE),) -> E005 | I8: =IF(I$1= VLOOKUP(I$1,Events!$A:$D,1,FALSE), VLOOKUP( VLOOKUP($A8,'[3]OSMEC ID + EVENT'!$A:$M,3,FALSE),Events!$B:$D,3,FALSE),) -> E006 | J8: =IF(J$1= VLOOKUP(J$1,Events!$A:$D,1,FALSE), VLOOKUP( VLOOKUP($A8,'[3]OSMEC ID + EVENT'!$A:$M,4,FALSE),Events!$B:$D,3,FALSE),) -> E007 | K8: =IF(K$1= VLOOKUP(K$1,Events!$A:$D,1,FALSE), VLOOKUP( VLOOKUP($A8,'[3]OSMEC ID + EVENT'!$A:$M,5,FALSE),Events!$B:$D,3,FALSE),) -> E008 | L8: =IF(L$1= VLOOKUP(L$1,Events!$A:$D,1,FALSE), VLOOKUP( VLOOKUP($A8,'[3]OSMEC ID + EVENT'!$A:$M,6,FALSE),Events!$B:$D,3,FALSE),) -> E009 | M8: =IF(M$1= VLOOKUP(M$1,Events!$A:$D,1,FALSE), VLOOKUP( VLOOKUP($A8,'[3]OSMEC ID + EVENT'!$A:$M,7,FALSE),Events!$B:$D,3,FALSE),) -> E010 | N8: =IF(N$1= VLOOKUP(N$1,Events!$A:$D,1,FALSE), VLOOKUP( VLOOKUP($A8,'[3]OSMEC ID + EVENT'!$A:$M,8,FALSE),Events!$B:$D,3,FALSE),) -> E011 | O8: =IF(O$1= VLOOKUP(O$1,Events!$A:$D,1,FALSE), VLOOKUP( VLOOKUP($A8,'[3]OSMEC ID + EVENT'!$A:$M,9,FALSE),Events!$B:$D,3,FALSE),) -> E012 | P8: =IF(P$1= VLOOKUP(P$1,Events!$A:$D,1,FALSE), VLOOKUP( VLOOKUP($A8,'[3]OSMEC ID + EVENT'!$A:$M,10,FALSE),Events!$B:$D,3,FALSE),) -> E013 | Q8: =IF(Q$1= VLOOKUP(Q$1,Events!$A:$D,1,FALSE), VLOOKUP( VLOOKUP($A8,'[3]OSMEC ID + EVENT'!$A:$M,11,FALSE),Events!$B:$D,3,FALSE),) -> E014 | R8: =IF(R$1= VLOOKUP(R$1,Events!$A:$D,1,FALSE), VLOOKUP( VLOOKUP($A8,'[3]OSMEC ID + EVENT'!$A:$M,12,FALSE),Events!$B:$D,3,FALSE),) -> E015 | S8: =IF(S$1= VLOOKUP(S$1,Events!$A:$D,1,FALSE), VLOOKUP( VLOOKUP($A8,'[3]OSMEC ID + EVENT'!$A:$M,13,FALSE),Events!$B:$D,3,FALSE),) -> E016 | T8: =IF( ISNA(MATCH(T$1,Events!$A:$A,0)), 0, VLOOKUP( VLOOKUP(A8,'[4]OSMEC ID + EVENT'!$A:$I,2,FALSE),Events!$B:$D,3,FALSE)) -> E017 | U8: =IF( ISNA(MATCH(U$1,Events!$A:$A,0)), 0, VLOOKUP( VLOOKUP($A8,'[4]OSMEC ID + EVENT'!$A:$I,3,FALSE),Events!$B:$D,3,FALSE)) -> E018 | V8: =IF( ISNA(MATCH(V$1,Events!$A:$A,0)), 0, VLOOKUP( VLOOKUP($A8,'[4]OSMEC ID + EVENT'!$A:$I,4,FALSE),Events!$B:$D,3,FALSE)) -> E019 | W8: =IF( ISNA(MATCH(W$1,Events!$A:$A,0)), 0, VLOOKUP( VLOOKUP($A8,'[4]OSMEC ID + EVENT'!$A:$I,5,FALSE),Events!$B:$D,3,FALSE)) -> E020 | X8: =IF( ISNA(MATCH(X$1,Events!$A:$A,0)), 0, VLOOKUP( VLOOKUP($A8,'[4]OSMEC ID + EVENT'!$A:$I,6,FALSE),Events!$B:$D,3,FALSE)) -> E021 | Y8: =IF( ISNA(MATCH(Y$1,Events!$A:$A,0)), 0, VLOOKUP( VLOOKUP($A8,'[4]OSMEC ID + EVENT'!$A:$I,7,FALSE),Events!$B:$D,3,FALSE)) -> E022 | Z8: =IF( ISNA(MATCH(Z$1,Events!$A:$A,0)), 0, VLOOKUP( VLOOKUP($A8,'[4]OSMEC ID + EVENT'!$A:$I,8,FALSE),Events!$B:$D,3,FALSE)) -> E023 | AA8: =IFERROR( VLOOKUP( VLOOKUP(A8,'[5]OSMEC ID + SUBJECT'!$A:$B,2,FALSE),Subjects!$B:$D,3,FALSE),"") | AB8: =IFERROR( VLOOKUP( VLOOKUP(A8,'[6]OSMEC ID + SUBJECT'!$A:$B,2,FALSE),Subjects!B:D,3,FALSE),"") -> S005 | AC8: =IFERROR( VLOOKUP( VLOOKUP(A8,'[7]OSMEC-ID + SESSION'!$A:$B,2,FALSE),Subjects!$B:$D,3,FALSE),"") | AD8: =IFERROR( VLOOKUP( VLOOKUP(A8,'[8]OSMEC ID + SESSION'!$A:$B,2,FALSE),Subjects!$B:$D,3,FALSE),"") | AE8: =IFERROR( VLOOKUP( VLOOKUP(A8,'[9]OSMEC ID + SUBJECT'!$A:$B,2,FALSE),Subjects!$B:$D,3,FALSE),"") | AF8: =IFERROR( VLOOKUP( VLOOKUP(A8,'[10]OSMEC ID + SESSION'!$A:$B,2,FALSE),Subjects!$B:$D,3),"")
A9: =Deligate_List!A9 -> OSMEC-0013 | B9: =VLOOKUP(A9,Deligate_List!A:B,2,FALSE) -> ABDUL RIYAAN AHMED | C9: =IFERROR( VLOOKUP( VLOOKUP($A9,'[1]OSMEC ID + WORKSHOP'!$A:$B,2,FALSE),Workshop!A:C,3,FALSE),"") -> W007 | D9: =IF($D$1 =Events!$A$2, VLOOKUP( VLOOKUP($A9,'[2]OSMEC ID + EVENT'!$A:$E,2,FALSE),Events!$B:$D,3,FALSE)) -> E001 | E9: =IF(E$1=Events!$A$3, VLOOKUP( VLOOKUP($A9,'[2]OSMEC ID + EVENT'!$A:$E,3,FALSE),Events!B:D,3,FALSE)) -> E002 | F9: =IF($F$1=Events!$A$4, VLOOKUP( VLOOKUP($A11,'[2]OSMEC ID + EVENT'!$A:$E,4,FALSE),Events!B:D,3,FALSE),) -> E003 | G9: =IF($G$1=Events!$A$5, VLOOKUP( VLOOKUP($A11,'[2]OSMEC ID + EVENT'!$A:$E,5,FALSE),Events!$B:$D,3,FALSE),) -> E004 | H9: =IF($H$1= VLOOKUP($H$1,Events!$A:$D,1,FALSE), VLOOKUP( VLOOKUP(A9,'[3]OSMEC ID + EVENT'!$A:$M,2,FALSE),Events!B:D,3,FALSE),) -> E005 | I9: =IF(I$1= VLOOKUP(I$1,Events!$A:$D,1,FALSE), VLOOKUP( VLOOKUP($A9,'[3]OSMEC ID + EVENT'!$A:$M,3,FALSE),Events!$B:$D,3,FALSE),) -> E006 | J9: =IF(J$1= VLOOKUP(J$1,Events!$A:$D,1,FALSE), VLOOKUP( VLOOKUP($A9,'[3]OSMEC ID + EVENT'!$A:$M,4,FALSE),Events!$B:$D,3,FALSE),) -> E007 | K9: =IF(K$1= VLOOKUP(K$1,Events!$A:$D,1,FALSE), VLOOKUP( VLOOKUP($A9,'[3]OSMEC ID + EVENT'!$A:$M,5,FALSE),Events!$B:$D,3,FALSE),) -> E008 | L9: =IF(L$1= VLOOKUP(L$1,Events!$A:$D,1,FALSE), VLOOKUP( VLOOKUP($A9,'[3]OSMEC ID + EVENT'!$A:$M,6,FALSE),Events!$B:$D,3,FALSE),) -> E009 | M9: =IF(M$1= VLOOKUP(M$1,Events!$A:$D,1,FALSE), VLOOKUP( VLOOKUP($A9,'[3]OSMEC ID + EVENT'!$A:$M,7,FALSE),Events!$B:$D,3,FALSE),) -> E010 | N9: =IF(N$1= VLOOKUP(N$1,Events!$A:$D,1,FALSE), VLOOKUP( VLOOKUP($A9,'[3]OSMEC ID + EVENT'!$A:$M,8,FALSE),Events!$B:$D,3,FALSE),) -> E011 | O9: =IF(O$1= VLOOKUP(O$1,Events!$A:$D,1,FALSE), VLOOKUP( VLOOKUP($A9,'[3]OSMEC ID + EVENT'!$A:$M,9,FALSE),Events!$B:$D,3,FALSE),) -> E012 | P9: =IF(P$1= VLOOKUP(P$1,Events!$A:$D,1,FALSE), VLOOKUP( VLOOKUP($A9,'[3]OSMEC ID + EVENT'!$A:$M,10,FALSE),Events!$B:$D,3,FALSE),) -> E013 | Q9: =IF(Q$1= VLOOKUP(Q$1,Events!$A:$D,1,FALSE), VLOOKUP( VLOOKUP($A9,'[3]OSMEC ID + EVENT'!$A:$M,11,FALSE),Events!$B:$D,3,FALSE),) -> E014 | R9: =IF(R$1= VLOOKUP(R$1,Events!$A:$D,1,FALSE), VLOOKUP( VLOOKUP($A9,'[3]OSMEC ID + EVENT'!$A:$M,12,FALSE),Events!$B:$D,3,FALSE),) -> E015 | S9: =IF(S$1= VLOOKUP(S$1,Events!$A:$D,1,FALSE), VLOOKUP( VLOOKUP($A9,'[3]OSMEC ID + EVENT'!$A:$M,13,FALSE),Events!$B:$D,3,FALSE),) -> E016 | T9: =IF( ISNA(MATCH(T$1,Events!$A:$A,0)), 0, VLOOKUP( VLOOKUP(A9,'[4]OSMEC ID + EVENT'!$A:$I,2,FALSE),Events!$B:$D,3,FALSE)) -> E017 | U9: =IF( ISNA(MATCH(U$1,Events!$A:$A,0)), 0, VLOOKUP( VLOOKUP($A9,'[4]OSMEC ID + EVENT'!$A:$I,3,FALSE),Events!$B:$D,3,FALSE)) -> E018 | V9: =IF( ISNA(MATCH(V$1,Events!$A:$A,0)), 0, VLOOKUP( VLOOKUP($A9,'[4]OSMEC ID + EVENT'!$A:$I,4,FALSE),Events!$B:$D,3,FALSE)) -> E019 | W9: =IF( ISNA(MATCH(W$1,Events!$A:$A,0)), 0, VLOOKUP( VLOOKUP($A9,'[4]OSMEC ID + EVENT'!$A:$I,5,FALSE),Events!$B:$D,3,FALSE)) -> E020 | X9: =IF( ISNA(MATCH(X$1,Events!$A:$A,0)), 0, VLOOKUP( VLOOKUP($A9,'[4]OSMEC ID + EVENT'!$A:$I,6,FALSE),Events!$B:$D,3,FALSE)) -> E021 | Y9: =IF( ISNA(MATCH(Y$1,Events!$A:$A,0)), 0, VLOOKUP( VLOOKUP($A9,'[4]OSMEC ID + EVENT'!$A:$I,7,FALSE),Events!$B:$D,3,FALSE)) -> E022 | Z9: =IF( ISNA(MATCH(Z$1,Events!$A:$A,0)), 0, VLOOKUP( VLOOKUP($A9,'[4]OSMEC ID + EVENT'!$A:$I,8,FALSE),Events!$B:$D,3,FALSE)) -> E023 | AA9: =IFERROR( VLOOKUP( VLOOKUP(A9,'[5]OSMEC ID + SUBJECT'!$A:$B,2,FALSE),Subjects!$B:$D,3,FALSE),"") | AB9: =IFERROR( VLOOKUP( VLOOKUP(A9,'[6]OSMEC ID + SUBJECT'!$A:$B,2,FALSE),Subjects!B:D,3,FALSE),"") | AC9: =IFERROR( VLOOKUP( VLOOKUP(A9,'[7]OSMEC-ID + SESSION'!$A:$B,2,FALSE),Subjects!$B:$D,3,FALSE),"") | AD9: =IFERROR( VLOOKUP( VLOOKUP(A9,'[8]OSMEC ID + SESSION'!$A:$B,2,FALSE),Subjects!$B:$D,3,FALSE),"") | AE9: =IFERROR( VLOOKUP( VLOOKUP(A9,'[9]OSMEC ID + SUBJECT'!$A:$B,2,FALSE),Subjects!$B:$D,3,FALSE),"") | AF9: =IFERROR( VLOOKUP( VLOOKUP(A9,'[10]OSMEC ID + SESSION'!$A:$B,2,FALSE),Subjects!$B:$D,3),"")
A10: =Deligate_List!A10 -> OSMEC-0008 | B10: =VLOOKUP(A10,Deligate_List!A:B,2,FALSE) -> SUHAS KAVALI | C10: =IFERROR( VLOOKUP( VLOOKUP($A10,'[1]OSMEC ID + WORKSHOP'!$A:$B,2,FALSE),Workshop!A:C,3,FALSE),"") -> W009 | D10: =IF($D$1 =Events!$A$2, VLOOKUP( VLOOKUP($A10,'[2]OSMEC ID + EVENT'!$A:$E,2,FALSE),Events!$B:$D,3,FALSE)) -> E001 | E10: =IF(E$1=Events!$A$3, VLOOKUP( VLOOKUP($A10,'[2]OSMEC ID + EVENT'!$A:$E,3,FALSE),Events!B:D,3,FALSE)) -> E002 | F10: =IF($F$1=Events!$A$4, VLOOKUP( VLOOKUP($A12,'[2]OSMEC ID + EVENT'!$A:$E,4,FALSE),Events!B:D,3,FALSE),) -> E003 | G10: =IF($G$1=Events!$A$5, VLOOKUP( VLOOKUP($A12,'[2]OSMEC ID + EVENT'!$A:$E,5,FALSE),Events!$B:$D,3,FALSE),) -> E004 | H10: =IF($H$1= VLOOKUP($H$1,Events!$A:$D,1,FALSE), VLOOKUP( VLOOKUP(A10,'[3]OSMEC ID + EVENT'!$A:$M,2,FALSE),Events!B:D,3,FALSE),) -> E005 | I10: =IF(I$1= VLOOKUP(I$1,Events!$A:$D,1,FALSE), VLOOKUP( VLOOKUP($A10,'[3]OSMEC ID + EVENT'!$A:$M,3,FALSE),Events!$B:$D,3,FALSE),) -> E006 | J10: =IF(J$1= VLOOKUP(J$1,Events!$A:$D,1,FALSE), VLOOKUP( VLOOKUP($A10,'[3]OSMEC ID + EVENT'!$A:$M,4,FALSE),Events!$B:$D,3,FALSE),) -> E007 | K10: =IF(K$1= VLOOKUP(K$1,Events!$A:$D,1,FALSE), VLOOKUP( VLOOKUP($A10,'[3]OSMEC ID + EVENT'!$A:$M,5,FALSE),Events!$B:$D,3,FALSE),) -> E008 | L10: =IF(L$1= VLOOKUP(L$1,Events!$A:$D,1,FALSE), VLOOKUP( VLOOKUP($A10,'[3]OSMEC ID + EVENT'!$A:$M,6,FALSE),Events!$B:$D,3,FALSE),) -> E009 | M10: =IF(M$1= VLOOKUP(M$1,Events!$A:$D,1,FALSE), VLOOKUP( VLOOKUP($A10,'[3]OSMEC ID + EVENT'!$A:$M,7,FALSE),Events!$B:$D,3,FALSE),) -> E010 | N10: =IF(N$1= VLOOKUP(N$1,Events!$A:$D,1,FALSE), VLOOKUP( VLOOKUP($A10,'[3]OSMEC ID + EVENT'!$A:$M,8,FALSE),Events!$B:$D,3,FALSE),) -> E011 | O10: =IF(O$1= VLOOKUP(O$1,Events!$A:$D,1,FALSE), VLOOKUP( VLOOKUP($A10,'[3]OSMEC ID + EVENT'!$A:$M,9,FALSE),Events!$B:$D,3,FALSE),) -> E012 | P10: =IF(P$1= VLOOKUP(P$1,Events!$A:$D,1,FALSE), VLOOKUP( VLOOKUP($A10,'[3]OSMEC ID + EVENT'!$A:$M,10,FALSE),Events!$B:$D,3,FALSE),) -> E013 | Q10: =IF(Q$1= VLOOKUP(Q$1,Events!$A:$D,1,FALSE), VLOOKUP( VLOOKUP($A10,'[3]OSMEC ID + EVENT'!$A:$M,11,FALSE),Events!$B:$D,3,FALSE),) -> E014 | R10: =IF(R$1= VLOOKUP(R$1,Events!$A:$D,1,FALSE), VLOOKUP( VLOOKUP($A10,'[3]OSMEC ID + EVENT'!$A:$M,12,FALSE),Events!$B:$D,3,FALSE),) -> E015 | S10: =IF(S$1= VLOOKUP(S$1,Events!$A:$D,1,FALSE), VLOOKUP( VLOOKUP($A10,'[3]OSMEC ID + EVENT'!$A:$M,13,FALSE),Events!$B:$D,3,FALSE),) -> E016 | T10: =IF( ISNA(MATCH(T$1,Events!$A:$A,0)), 0, VLOOKUP( VLOOKUP(A10,'[4]OSMEC ID + EVENT'!$A:$I,2,FALSE),Events!$B:$D,3,FALSE)) -> E017 | U10: =IF( ISNA(MATCH(U$1,Events!$A:$A,0)), 0, VLOOKUP( VLOOKUP($A10,'[4]OSMEC ID + EVENT'!$A:$I,3,FALSE),Events!$B:$D,3,FALSE)) -> E018 | V10: =IF( ISNA(MATCH(V$1,Events!$A:$A,0)), 0, VLOOKUP( VLOOKUP($A10,'[4]OSMEC ID + EVENT'!$A:$I,4,FALSE),Events!$B:$D,3,FALSE)) -> E019 | W10: =IF( ISNA(MATCH(W$1,Events!$A:$A,0)), 0, VLOOKUP( VLOOKUP($A10,'[4]OSMEC ID + EVENT'!$A:$I,5,FALSE),Events!$B:$D,3,FALSE)) -> E020 | X10: =IF( ISNA(MATCH(X$1,Events!$A:$A,0)), 0, VLOOKUP( VLOOKUP($A10,'[4]OSMEC ID + EVENT'!$A:$I,6,FALSE),Events!$B:$D,3,FALSE)) -> E021 | Y10: =IF( ISNA(MATCH(Y$1,Events!$A:$A,0)), 0, VLOOKUP( VLOOKUP($A10,'[4]OSMEC ID + EVENT'!$A:$I,7,FALSE),Events!$B:$D,3,FALSE)) -> E022 | Z10: =IF( ISNA(MATCH(Z$1,Events!$A:$A,0)), 0, VLOOKUP( VLOOKUP($A10,'[4]OSMEC ID + EVENT'!$A:$I,8,FALSE),Events!$B:$D,3,FALSE)) -> E023 | AA10: =IFERROR( VLOOKUP( VLOOKUP(A10,'[5]OSMEC ID + SUBJECT'!$A:$B,2,FALSE),Subjects!$B:$D,3,FALSE),"") | AB10: =IFERROR( VLOOKUP( VLOOKUP(A10,'[6]OSMEC ID + SUBJECT'!$A:$B,2,FALSE),Subjects!B:D,3,FALSE),"") | AC10: =IFERROR( VLOOKUP( VLOOKUP(A10,'[7]OSMEC-ID + SESSION'!$A:$B,2,FALSE),Subjects!$B:$D,3,FALSE),"") | AD10: =IFERROR( VLOOKUP( VLOOKUP(A10,'[8]OSMEC ID + SESSION'!$A:$B,2,FALSE),Subjects!$B:$D,3,FALSE),"") | AE10: =IFERROR( VLOOKUP( VLOOKUP(A10,'[9]OSMEC ID + SUBJECT'!$A:$B,2,FALSE),Subjects!$B:$D,3,FALSE),"") | AF10: =IFERROR( VLOOKUP( VLOOKUP(A10,'[10]OSMEC ID + SESSION'!$A:$B,2,FALSE),Subjects!$B:$D,3),"")
A11: =Deligate_List!A11 -> OSMEC-0012 | B11: =VLOOKUP(A11,Deligate_List!A:B,2,FALSE) -> KASI ALEKHYA SRI | C11: =IFERROR( VLOOKUP( VLOOKUP($A11,'[1]OSMEC ID + WORKSHOP'!$A:$B,2,FALSE),Workshop!A:C,3,FALSE),"") | D11: =IF($D$1 =Events!$A$2, VLOOKUP( VLOOKUP($A11,'[2]OSMEC ID + EVENT'!$A:$E,2,FALSE),Events!$B:$D,3,FALSE)) -> E001 | E11: =IF(E$1=Events!$A$3, VLOOKUP( VLOOKUP($A11,'[2]OSMEC ID + EVENT'!$A:$E,3,FALSE),Events!B:D,3,FALSE)) -> E002 | F11: =IF($F$1=Events!$A$4, VLOOKUP( VLOOKUP($A13,'[2]OSMEC ID + EVENT'!$A:$E,4,FALSE),Events!B:D,3,FALSE),) -> E003 | G11: =IF($G$1=Events!$A$5, VLOOKUP( VLOOKUP($A13,'[2]OSMEC ID + EVENT'!$A:$E,5,FALSE),Events!$B:$D,3,FALSE),) -> E004 | H11: =IF($H$1= VLOOKUP($H$1,Events!$A:$D,1,FALSE), VLOOKUP( VLOOKUP(A11,'[3]OSMEC ID + EVENT'!$A:$M,2,FALSE),Events!B:D,3,FALSE),) -> E005 | I11: =IF(I$1= VLOOKUP(I$1,Events!$A:$D,1,FALSE), VLOOKUP( VLOOKUP($A11,'[3]OSMEC ID + EVENT'!$A:$M,3,FALSE),Events!$B:$D,3,FALSE),) -> E006 | J11: =IF(J$1= VLOOKUP(J$1,Events!$A:$D,1,FALSE), VLOOKUP( VLOOKUP($A11,'[3]OSMEC ID + EVENT'!$A:$M,4,FALSE),Events!$B:$D,3,FALSE),) -> E007 | K11: =IF(K$1= VLOOKUP(K$1,Events!$A:$D,1,FALSE), VLOOKUP( VLOOKUP($A11,'[3]OSMEC ID + EVENT'!$A:$M,5,FALSE),Events!$B:$D,3,FALSE),) -> E008 | L11: =IF(L$1= VLOOKUP(L$1,Events!$A:$D,1,FALSE), VLOOKUP( VLOOKUP($A11,'[3]OSMEC ID + EVENT'!$A:$M,6,FALSE),Events!$B:$D,3,FALSE),) -> E009 | M11: =IF(M$1= VLOOKUP(M$1,Events!$A:$D,1,FALSE), VLOOKUP( VLOOKUP($A11,'[3]OSMEC ID + EVENT'!$A:$M,7,FALSE),Events!$B:$D,3,FALSE),) -> E010 | N11: =IF(N$1= VLOOKUP(N$1,Events!$A:$D,1,FALSE), VLOOKUP( VLOOKUP($A11,'[3]OSMEC ID + EVENT'!$A:$M,8,FALSE),Events!$B:$D,3,FALSE),) -> E011 | O11: =IF(O$1= VLOOKUP(O$1,Events!$A:$D,1,FALSE), VLOOKUP( VLOOKUP($A11,'[3]OSMEC ID + EVENT'!$A:$M,9,FALSE),Events!$B:$D,3,FALSE),) -> E012 | P11: =IF(P$1= VLOOKUP(P$1,Events!$A:$D,1,FALSE), VLOOKUP( VLOOKUP($A11,'[3]OSMEC ID + EVENT'!$A:$M,10,FALSE),Events!$B:$D,3,FALSE),) -> E013 | Q11: =IF(Q$1= VLOOKUP(Q$1,Events!$A:$D,1,FALSE), VLOOKUP( VLOOKUP($A11,'[3]OSMEC ID + EVENT'!$A:$M,11,FALSE),Events!$B:$D,3,FALSE),) -> E014 | R11: =IF(R$1= VLOOKUP(R$1,Events!$A:$D,1,FALSE), VLOOKUP( VLOOKUP($A11,'[3]OSMEC ID + EVENT'!$A:$M,12,FALSE),Events!$B:$D,3,FALSE),) -> E015 | S11: =IF(S$1= VLOOKUP(S$1,Events!$A:$D,1,FALSE), VLOOKUP( VLOOKUP($A11,'[3]OSMEC ID + EVENT'!$A:$M,13,FALSE),Events!$B:$D,3,FALSE),) -> E016 | T11: =IF( ISNA(MATCH(T$1,Events!$A:$A,0)), 0, VLOOKUP( VLOOKUP(A11,'[4]OSMEC ID + EVENT'!$A:$I,2,FALSE),Events!$B:$D,3,FALSE)) -> E017 | U11: =IF( ISNA(MATCH(U$1,Events!$A:$A,0)), 0, VLOOKUP( VLOOKUP($A11,'[4]OSMEC ID + EVENT'!$A:$I,3,FALSE),Events!$B:$D,3,FALSE)) -> E018 | V11: =IF( ISNA(MATCH(V$1,Events!$A:$A,0)), 0, VLOOKUP( VLOOKUP($A11,'[4]OSMEC ID + EVENT'!$A:$I,4,FALSE),Events!$B:$D,3,FALSE)) -> E019 | W11: =IF( ISNA(MATCH(W$1,Events!$A:$A,0)), 0, VLOOKUP( VLOOKUP($A11,'[4]OSMEC ID + EVENT'!$A:$I,5,FALSE),Events!$B:$D,3,FALSE)) -> E020 | X11: =IF( ISNA(MATCH(X$1,Events!$A:$A,0)), 0, VLOOKUP( VLOOKUP($A11,'[4]OSMEC ID + EVENT'!$A:$I,6,FALSE),Events!$B:$D,3,FALSE)) -> E021 | Y11: =IF( ISNA(MATCH(Y$1,Events!$A:$A,0)), 0, VLOOKUP( VLOOKUP($A11,'[4]OSMEC ID + EVENT'!$A:$I,7,FALSE),Events!$B:$D,3,FALSE)) -> E022 | Z11: =IF( ISNA(MATCH(Z$1,Events!$A:$A,0)), 0, VLOOKUP( VLOOKUP($A11,'[4]OSMEC ID + EVENT'!$A:$I,8,FALSE),Events!$B:$D,3,FALSE)) -> E023 | AA11: =IFERROR( VLOOKUP( VLOOKUP(A11,'[5]OSMEC ID + SUBJECT'!$A:$B,2,FALSE),Subjects!$B:$D,3,FALSE),"") | AB11: =IFERROR( VLOOKUP( VLOOKUP(A11,'[6]OSMEC ID + SUBJECT'!$A:$B,2,FALSE),Subjects!B:D,3,FALSE),"") | AC11: =IFERROR( VLOOKUP( VLOOKUP(A11,'[7]OSMEC-ID + SESSION'!$A:$B,2,FALSE),Subjects!$B:$D,3,FALSE),"") | AD11: =IFERROR( VLOOKUP( VLOOKUP(A11,'[8]OSMEC ID + SESSION'!$A:$B,2,FALSE),Subjects!$B:$D,3,FALSE),"") | AE11: =IFERROR( VLOOKUP( VLOOKUP(A11,'[9]OSMEC ID + SUBJECT'!$A:$B,2,FALSE),Subjects!$B:$D,3,FALSE),"") | AF11: =IFERROR( VLOOKUP( VLOOKUP(A11,'[10]OSMEC ID + SESSION'!$A:$B,2,FALSE),Subjects!$B:$D,3),"")
A12: =Deligate_List!A12 -> OSMEC-0023 | B12: =VLOOKUP(A12,Deligate_List!A:B,2,FALSE) -> Arshi Ameena Khan | C12: =IFERROR( VLOOKUP( VLOOKUP($A12,'[1]OSMEC ID + WORKSHOP'!$A:$B,2,FALSE),Workshop!A:C,3,FALSE),"") -> W012 | D12: =IF($D$1 =Events!$A$2, VLOOKUP( VLOOKUP($A12,'[2]OSMEC ID + EVENT'!$A:$E,2,FALSE),Events!$B:$D,3,FALSE)) -> E001 | E12: =IF(E$1=Events!$A$3, VLOOKUP( VLOOKUP($A12,'[2]OSMEC ID + EVENT'!$A:$E,3,FALSE),Events!B:D,3,FALSE)) -> E002 | F12: =IF($F$1=Events!$A$4, VLOOKUP( VLOOKUP($A14,'[2]OSMEC ID + EVENT'!$A:$E,4,FALSE),Events!B:D,3,FALSE),) -> E003 | G12: =IF($G$1=Events!$A$5, VLOOKUP( VLOOKUP($A14,'[2]OSMEC ID + EVENT'!$A:$E,5,FALSE),Events!$B:$D,3,FALSE),) -> E004 | H12: =IF($H$1= VLOOKUP($H$1,Events!$A:$D,1,FALSE), VLOOKUP( VLOOKUP(A12,'[3]OSMEC ID + EVENT'!$A:$M,2,FALSE),Events!B:D,3,FALSE),) -> E005 | I12: =IF(I$1= VLOOKUP(I$1,Events!$A:$D,1,FALSE), VLOOKUP( VLOOKUP($A12,'[3]OSMEC ID + EVENT'!$A:$M,3,FALSE),Events!$B:$D,3,FALSE),) -> E006 | J12: =IF(J$1= VLOOKUP(J$1,Events!$A:$D,1,FALSE), VLOOKUP( VLOOKUP($A12,'[3]OSMEC ID + EVENT'!$A:$M,4,FALSE),Events!$B:$D,3,FALSE),) -> E007 | K12: =IF(K$1= VLOOKUP(K$1,Events!$A:$D,1,FALSE), VLOOKUP( VLOOKUP($A12,'[3]OSMEC ID + EVENT'!$A:$M,5,FALSE),Events!$B:$D,3,FALSE),) -> E008 | L12: =IF(L$1= VLOOKUP(L$1,Events!$A:$D,1,FALSE), VLOOKUP( VLOOKUP($A12,'[3]OSMEC ID + EVENT'!$A:$M,6,FALSE),Events!$B:$D,3,FALSE),) -> E009 | M12: =IF(M$1= VLOOKUP(M$1,Events!$A:$D,1,FALSE), VLOOKUP( VLOOKUP($A12,'[3]OSMEC ID + EVENT'!$A:$M,7,FALSE),Events!$B:$D,3,FALSE),) -> E010 | N12: =IF(N$1= VLOOKUP(N$1,Events!$A:$D,1,FALSE), VLOOKUP( VLOOKUP($A12,'[3]OSMEC ID + EVENT'!$A:$M,8,FALSE),Events!$B:$D,3,FALSE),) -> E011 | O12: =IF(O$1= VLOOKUP(O$1,Events!$A:$D,1,FALSE), VLOOKUP( VLOOKUP($A12,'[3]OSMEC ID + EVENT'!$A:$M,9,FALSE),Events!$B:$D,3,FALSE),) -> E012 | P12: =IF(P$1= VLOOKUP(P$1,Events!$A:$D,1,FALSE), VLOOKUP( VLOOKUP($A12,'[3]OSMEC ID + EVENT'!$A:$M,10,FALSE),Events!$B:$D,3,FALSE),) -> E013 | Q12: =IF(Q$1= VLOOKUP(Q$1,Events!$A:$D,1,FALSE), VLOOKUP( VLOOKUP($A12,'[3]OSMEC ID + EVENT'!$A:$M,11,FALSE),Events!$B:$D,3,FALSE),) -> E014 | R12: =IF(R$1= VLOOKUP(R$1,Events!$A:$D,1,FALSE), VLOOKUP( VLOOKUP($A12,'[3]OSMEC ID + EVENT'!$A:$M,12,FALSE),Events!$B:$D,3,FALSE),) -> E015 | S12: =IF(S$1= VLOOKUP(S$1,Events!$A:$D,1,FALSE), VLOOKUP( VLOOKUP($A12,'[3]OSMEC ID + EVENT'!$A:$M,13,FALSE),Events!$B:$D,3,FALSE),) -> E016 | T12: =IF( ISNA(MATCH(T$1,Events!$A:$A,0)), 0, VLOOKUP( VLOOKUP(A12,'[4]OSMEC ID + EVENT'!$A:$I,2,FALSE),Events!$B:$D,3,FALSE)) -> E017 | U12: =IF( ISNA(MATCH(U$1,Events!$A:$A,0)), 0, VLOOKUP( VLOOKUP($A12,'[4]OSMEC ID + EVENT'!$A:$I,3,FALSE),Events!$B:$D,3,FALSE)) -> E018 | V12: =IF( ISNA(MATCH(V$1,Events!$A:$A,0)), 0, VLOOKUP( VLOOKUP($A12,'[4]OSMEC ID + EVENT'!$A:$I,4,FALSE),Events!$B:$D,3,FALSE)) -> E019 | W12: =IF( ISNA(MATCH(W$1,Events!$A:$A,0)), 0, VLOOKUP( VLOOKUP($A12,'[4]OSMEC ID + EVENT'!$A:$I,5,FALSE),Events!$B:$D,3,FALSE)) -> E020 | X12: =IF( ISNA(MATCH(X$1,Events!$A:$A,0)), 0, VLOOKUP( VLOOKUP($A12,'[4]OSMEC ID + EVENT'!$A:$I,6,FALSE),Events!$B:$D,3,FALSE)) -> E021 | Y12: =IF( ISNA(MATCH(Y$1,Events!$A:$A,0)), 0, VLOOKUP( VLOOKUP($A12,'[4]OSMEC ID + EVENT'!$A:$I,7,FALSE),Events!$B:$D,3,FALSE)) -> E022 | Z12: =IF( ISNA(MATCH(Z$1,Events!$A:$A,0)), 0, VLOOKUP( VLOOKUP($A12,'[4]OSMEC ID + EVENT'!$A:$I,8,FALSE),Events!$B:$D,3,FALSE)) -> E023 | AA12: =IFERROR( VLOOKUP( VLOOKUP(A12,'[5]OSMEC ID + SUBJECT'!$A:$B,2,FALSE),Subjects!$B:$D,3,FALSE),"") | AB12: =IFERROR( VLOOKUP( VLOOKUP(A12,'[6]OSMEC ID + SUBJECT'!$A:$B,2,FALSE),Subjects!B:D,3,FALSE),"") | AC12: =IFERROR( VLOOKUP( VLOOKUP(A12,'[7]OSMEC-ID + SESSION'!$A:$B,2,FALSE),Subjects!$B:$D,3,FALSE),"") | AD12: =IFERROR( VLOOKUP( VLOOKUP(A12,'[8]OSMEC ID + SESSION'!$A:$B,2,FALSE),Subjects!$B:$D,3,FALSE),"") | AE12: =IFERROR( VLOOKUP( VLOOKUP(A12,'[9]OSMEC ID + SUBJECT'!$A:$B,2,FALSE),Subjects!$B:$D,3,FALSE),"") | AF12: =IFERROR( VLOOKUP( VLOOKUP(A12,'[10]OSMEC ID + SESSION'!$A:$B,2,FALSE),Subjects!$B:$D,3),"")
A13: =Deligate_List!A13 -> OSMEC-0011 | B13: =VLOOKUP(A13,Deligate_List!A:B,2,FALSE) -> SAFA MOHIUDDIN | C13: =IFERROR( VLOOKUP( VLOOKUP($A13,'[1]OSMEC ID + WORKSHOP'!$A:$B,2,FALSE),Workshop!A:C,3,FALSE),"") -> W001 | D13: =IF($D$1 =Events!$A$2, VLOOKUP( VLOOKUP($A13,'[2]OSMEC ID + EVENT'!$A:$E,2,FALSE),Events!$B:$D,3,FALSE)) -> E001 | E13: =IF(E$1=Events!$A$3, VLOOKUP( VLOOKUP($A13,'[2]OSMEC ID + EVENT'!$A:$E,3,FALSE),Events!B:D,3,FALSE)) -> E002 | F13: =IF($F$1=Events!$A$4, VLOOKUP( VLOOKUP($A15,'[2]OSMEC ID + EVENT'!$A:$E,4,FALSE),Events!B:D,3,FALSE),) -> E003 | G13: =IF($G$1=Events!$A$5, VLOOKUP( VLOOKUP($A15,'[2]OSMEC ID + EVENT'!$A:$E,5,FALSE),Events!$B:$D,3,FALSE),) -> E004 | H13: =IF($H$1= VLOOKUP($H$1,Events!$A:$D,1,FALSE), VLOOKUP( VLOOKUP(A13,'[3]OSMEC ID + EVENT'!$A:$M,2,FALSE),Events!B:D,3,FALSE),) -> E005 | I13: =IF(I$1= VLOOKUP(I$1,Events!$A:$D,1,FALSE), VLOOKUP( VLOOKUP($A13,'[3]OSMEC ID + EVENT'!$A:$M,3,FALSE),Events!$B:$D,3,FALSE),) -> E006 | J13: =IF(J$1= VLOOKUP(J$1,Events!$A:$D,1,FALSE), VLOOKUP( VLOOKUP($A13,'[3]OSMEC ID + EVENT'!$A:$M,4,FALSE),Events!$B:$D,3,FALSE),) -> E007 | K13: =IF(K$1= VLOOKUP(K$1,Events!$A:$D,1,FALSE), VLOOKUP( VLOOKUP($A13,'[3]OSMEC ID + EVENT'!$A:$M,5,FALSE),Events!$B:$D,3,FALSE),) -> E008 | L13: =IF(L$1= VLOOKUP(L$1,Events!$A:$D,1,FALSE), VLOOKUP( VLOOKUP($A13,'[3]OSMEC ID + EVENT'!$A:$M,6,FALSE),Events!$B:$D,3,FALSE),) -> E009 | M13: =IF(M$1= VLOOKUP(M$1,Events!$A:$D,1,FALSE), VLOOKUP( VLOOKUP($A13,'[3]OSMEC ID + EVENT'!$A:$M,7,FALSE),Events!$B:$D,3,FALSE),) -> E010 | N13: =IF(N$1= VLOOKUP(N$1,Events!$A:$D,1,FALSE), VLOOKUP( VLOOKUP($A13,'[3]OSMEC ID + EVENT'!$A:$M,8,FALSE),Events!$B:$D,3,FALSE),) -> E011 | O13: =IF(O$1= VLOOKUP(O$1,Events!$A:$D,1,FALSE), VLOOKUP( VLOOKUP($A13,'[3]OSMEC ID + EVENT'!$A:$M,9,FALSE),Events!$B:$D,3,FALSE),) -> E012 | P13: =IF(P$1= VLOOKUP(P$1,Events!$A:$D,1,FALSE), VLOOKUP( VLOOKUP($A13,'[3]OSMEC ID + EVENT'!$A:$M,10,FALSE),Events!$B:$D,3,FALSE),) -> E013 | Q13: =IF(Q$1= VLOOKUP(Q$1,Events!$A:$D,1,FALSE), VLOOKUP( VLOOKUP($A13,'[3]OSMEC ID + EVENT'!$A:$M,11,FALSE),Events!$B:$D,3,FALSE),) -> E014 | R13: =IF(R$1= VLOOKUP(R$1,Events!$A:$D,1,FALSE), VLOOKUP( VLOOKUP($A13,'[3]OSMEC ID + EVENT'!$A:$M,12,FALSE),Events!$B:$D,3,FALSE),) -> E015 | S13: =IF(S$1= VLOOKUP(S$1,Events!$A:$D,1,FALSE), VLOOKUP( VLOOKUP($A13,'[3]OSMEC ID + EVENT'!$A:$M,13,FALSE),Events!$B:$D,3,FALSE),) -> E016 | T13: =IF( ISNA(MATCH(T$1,Events!$A:$A,0)), 0, VLOOKUP( VLOOKUP(A13,'[4]OSMEC ID + EVENT'!$A:$I,2,FALSE),Events!$B:$D,3,FALSE)) -> E017 | U13: =IF( ISNA(MATCH(U$1,Events!$A:$A,0)), 0, VLOOKUP( VLOOKUP($A13,'[4]OSMEC ID + EVENT'!$A:$I,3,FALSE),Events!$B:$D,3,FALSE)) -> E018 | V13: =IF( ISNA(MATCH(V$1,Events!$A:$A,0)), 0, VLOOKUP( VLOOKUP($A13,'[4]OSMEC ID + EVENT'!$A:$I,4,FALSE),Events!$B:$D,3,FALSE)) -> E019 | W13: =IF( ISNA(MATCH(W$1,Events!$A:$A,0)), 0, VLOOKUP( VLOOKUP($A13,'[4]OSMEC ID + EVENT'!$A:$I,5,FALSE),Events!$B:$D,3,FALSE)) -> E020 | X13: =IF( ISNA(MATCH(X$1,Events!$A:$A,0)), 0, VLOOKUP( VLOOKUP($A13,'[4]OSMEC ID + EVENT'!$A:$I,6,FALSE),Events!$B:$D,3,FALSE)) -> E021 | Y13: =IF( ISNA(MATCH(Y$1,Events!$A:$A,0)), 0, VLOOKUP( VLOOKUP($A13,'[4]OSMEC ID + EVENT'!$A:$I,7,FALSE),Events!$B:$D,3,FALSE)) -> E022 | Z13: =IF( ISNA(MATCH(Z$1,Events!$A:$A,0)), 0, VLOOKUP( VLOOKUP($A13,'[4]OSMEC ID + EVENT'!$A:$I,8,FALSE),Events!$B:$D,3,FALSE)) -> E023 | AA13: =IFERROR( VLOOKUP( VLOOKUP(A13,'[5]OSMEC ID + SUBJECT'!$A:$B,2,FALSE),Subjects!$B:$D,3,FALSE),"") | AB13: =IFERROR( VLOOKUP( VLOOKUP(A13,'[6]OSMEC ID + SUBJECT'!$A:$B,2,FALSE),Subjects!B:D,3,FALSE),"") | AC13: =IFERROR( VLOOKUP( VLOOKUP(A13,'[7]OSMEC-ID + SESSION'!$A:$B,2,FALSE),Subjects!$B:$D,3,FALSE),"") | AD13: =IFERROR( VLOOKUP( VLOOKUP(A13,'[8]OSMEC ID + SESSION'!$A:$B,2,FALSE),Subjects!$B:$D,3,FALSE),"") | AE13: =IFERROR( VLOOKUP( VLOOKUP(A13,'[9]OSMEC ID + SUBJECT'!$A:$B,2,FALSE),Subjects!$B:$D,3,FALSE),"") | AF13: =IFERROR( VLOOKUP( VLOOKUP(A13,'[10]OSMEC ID + SESSION'!$A:$B,2,FALSE),Subjects!$B:$D,3),"")
